Workbook

Sheet Overview
F2: Store points value distribution
A3: Input | D3: Calculated | F3: Pack | G3: Kit | H3: Celebration | I3: Original
D4: Per user points value in the store | E4: =sum('Content plan'!J:J) -> 1686666.7 | F4: =SUMIF('Content plan'!$A:$A,F3,'Content plan'!$J:$J)/$E4 -> 0.64229249 | G4: =SUMIF('Content plan'!$A:$A,G3,'Content plan'!$J:$J)/$E4 -> 0.27124506 | H4: =SUMIF('Content plan'!$A:$A,H3,'Content plan'!$J:$J)/$E4 -> 0.086462451 | I4: =SUMIF('Content plan'!$A:$A,I3,'Content plan'!$J:$J)/$E4 -> 0
A6: MAU | B6: 805250 | D6: Per user USD value in the store | E6: =SUM('Content plan'!I:I) -> 404.8
A7: Payers | B7: =sum(E22:E24)/B6 -> 0.104 | D7: Per user monetization space (points) | E7: =B8-B9 -> 990000
A8: Acc points grinded by top active players | B8: =35000*30 -> 1050000 | H8: chart data
A9: Acc points grinded by most players | B9: =30*2000 -> 60000 | D9: ="Total rev packs ("&B6&" MAU)" -> Total rev packs (805250 MAU) | E9: =sum(J22:J24) -> 2508514.8 | H9: Points grinded by most | I9: =B9 -> 60000
A10: Originals rev share | B10: 0.7 | D10: ="Total rev kits ("&B6&" MAU)" -> Total rev kits (805250 MAU) | E10: =sum(L22:L24) -> 63397.01 | H10: Points grinded by top active players | I10: =B8 -> 1050000
D11: ="Total rev celebrations ("&B6&" MAU)" -> Total rev celebrations (805250 MAU) | E11: =sum(N22:N24) -> 148528.36 | H11: Accumulated points available in the Store | I11: =E4 -> 1686666.7
D12: ="Total rev originals ("&B6&" MAU)" -> Total rev originals (805250 MAU) | E12: =sum(P22:P24) -> 0
D13: ="Total originals after rev share ("&B6&" MAU)" -> Total originals after rev share (805250 MAU) | E13: =E12*B10 -> 0
A14: next steps | D14: ="Total rev ("&B6&" MAU)" -> Total rev (805250 MAU) | E14: =sum(E9:E12) -> 2720440.2
A15: kolla med frans en draft på packs | D15: ARPU | E15: =E14/B6 -> 3.3783796
A16: kolla med joacim en draft på kits | D16: ARPPU | E16: =E14/sum(E22:E24) -> 32.484419
A17: kolla celebrtions | D17: Store fulfillment vs monetisation space | E17: =E4/E7 -> 1.7037037
D18: Store fulfillment vs top grinders | E18: =E4/B8 -> 1.6063492
I20: Pack | K20: Kit | M20: Celebration | O20: Original
B21: % of total population | C21: Paying % | D21: Cohort total users | E21: Cohort total paying users | F21: ="Cohort total rev ("&B6&" MAU)" -> Cohort total rev (805250 MAU) | G21: Cohort ARPPU | H21: Cohort ARPU | I21: ARPPU | J21: ="Cohort total rev ("&B6&" MAU)" -> Cohort total rev (805250 MAU) | K21: ARPPU | L21: ="Cohort total rev ("&B6&" MAU)" -> Cohort total rev (805250 MAU) | M21: ARPPU | N21: ="Cohort total rev ("&B6&" MAU)" -> Cohort total rev (805250 MAU) | O21: ARPPU | P21: ="Cohort total rev ("&B6&" MAU)" -> Cohort total rev (805250 MAU)
A22: Persona 1: Core FUT (every day) | B22: 0.2 | C22: 0.3 | D22: =$B$6*B22 -> 161050 | E22: =C22*D22 -> 48315 | F22: =J22+L22+N22+P22 -> 2222417.5 | G22: =I22+K22+M22+O22 -> 45.9985 | H22: =F22/D22 -> 13.79955 | I22: =SUMPRODUCT(('Content plan'!$A$2:$A1001=I$20)*('Content plan'!$F$2:$F1001)*('Content plan'!$L$2:$L1001)) -> 43 | J22: =I22*$E22 -> 2077545 | K22: =SUMPRODUCT(('Content plan'!$A$2:$A1001=K$20)*('Content plan'!$F$2:$F1001)*('Content plan'!$L$2:$L1001)) -> 0.8985 | L22: =K22*$E22 -> 43411.027 | M22: =SUMPRODUCT(('Content plan'!$A$2:$A1001=M$20)*('Content plan'!$F$2:$F1001)*('Content plan'!$L$2:$L1001)) -> 2.1 | N22: =M22*$E22 -> 101461.5 | O22: =SUMPRODUCT(('Content plan'!$A$2:$A1001=O$20)*('Content plan'!$F$2:$F1001)*('Content plan'!$L$2:$L1001)) -> 0 | P22: =O22*$E22 -> 0
A23: Persona 2: Dedicated FUT (2-3 times / week) | B23: 0.35 | C23: 0.1 | D23: =$B$6*B23 -> 281837.5 | E23: =C23*D23 -> 28183.75 | F23: =J23+L23+N23+P23 -> 445556.9 | G23: =I23+K23+M23+O23 -> 15.809 | H23: =F23/D23 -> 1.5809 | I23: =SUMPRODUCT(('Content plan'!$A$2:$A1001=I$20)*('Content plan'!$F$2:$F1001)*('Content plan'!$M$2:$M1001)) -> 13.8 | J23: =I23*$E23 -> 388935.75 | K23: =SUMPRODUCT(('Content plan'!$A$2:$A1001=K$20)*('Content plan'!$F$2:$F1001)*('Content plan'!$M$2:$M1001)) -> 0.609 | L23: =K23*$E23 -> 17163.904 | M23: =SUMPRODUCT(('Content plan'!$A$2:$A1001=M$20)*('Content plan'!$F$2:$F1001)*('Content plan'!$M$2:$M1001)) -> 1.4 | N23: =M23*$E23 -> 39457.25 | O23: =SUMPRODUCT(('Content plan'!$A$2:$A1001=O$20)*('Content plan'!$F$2:$F1001)*('Content plan'!$M$2:$M1001)) -> 0 | P23: =O23*$E23 -> 0
A24: Persona 3: Casual FUT ( a few times / month) | B24: 0.45 | C24: 0.02 | D24: =$B$6*B24 -> 362362.5 | E24: =C24*D24 -> 7247.25 | F24: =J24+L24+N24+P24 -> 52465.742 | G24: =I24+K24+M24+O24 -> 7.2394 | H24: =F24/D24 -> 0.144788 | I24: =SUMPRODUCT(('Content plan'!$A$2:$A1001=I$20)*('Content plan'!$F$2:$F1001)*('Content plan'!$N$2:$N1001)) -> 5.8 | J24: =I24*$E24 -> 42034.05 | K24: =SUMPRODUCT(('Content plan'!$A$2:$A1001=K$20)*('Content plan'!$F$2:$F1001)*('Content plan'!$N$2:$N1001)) -> 0.3894 | L24: =K24*$E24 -> 2822.0792 | M24: =SUMPRODUCT(('Content plan'!$A$2:$A1001=M$20)*('Content plan'!$F$2:$F1001)*('Content plan'!$N$2:$N1001)) -> 1.05 | N24: =M24*$E24 -> 7609.6125 | O24: =SUMPRODUCT(('Content plan'!$A$2:$A1001=O$20)*('Content plan'!$F$2:$F1001)*('Content plan'!$N$2:$N1001)) -> 0 | P24: =O24*$E24 -> 0

Sheet Content plan
A1: Category | B1: SKU | C1: Set Points value | D1: or set USD value | E1: Units Available | F1: calc USD value | G1: calc Points value | H1: Coins | I1: Total value USD | J1: Total value Points | K1: Total value Coins | L1: Persona 1: Core FUT (every day) | M1: Persona 2: Dedicated FUT (2-3 times / week) | N1: Persona 3: Casual FUT ( a few times / month)
A2: Pack | B2: Standard Packs | D2: 6 | E2: 10 | F2: =IF(C2>0, C2/'Conversion rates'!$I$3, D2) -> 6 | G2: =IF(C2>0, C2, D2*'Conversion rates'!$I$3) -> 25000 | I2: =E2*F2 -> 60 | J2: =E2*G2 -> 250000 | L2: 0.5 | M2: 0.3 | N2: 0.3
A3: Pack | B3: Standard Packs expensive | D3: 20 | E3: 10 | F3: =IF(C3>0, C3/'Conversion rates'!$I$3, D3) -> 20 | G3: =IF(C3>0, C3, D3*'Conversion rates'!$I$3) -> 83333.333 | I3: =E3*F3 -> 200 | J3: =E3*G3 -> 833333.33 | L3: 2 | M3: 0.6 | N3: 0.2
A4: Kit | B4: Kits Internal | D4: 3.99 | E4: 10 | F4: =IF(C4>0, C4/'Conversion rates'!$I$3, D4) -> 3.99 | G4: =IF(C4>0, C4, D4*'Conversion rates'!$I$3) -> 16625 | I4: =E4*F4 -> 39.9 | J4: =E4*G4 -> 166250 | L4: 0.05 | M4: 0.03 | N4: 0.01
A5: Kit | B5: Kits Partnership | D5: 6.99 | E5: 10 | F5: =IF(C5>0, C5/'Conversion rates'!$I$3, D5) -> 6.99 | G5: =IF(C5>0, C5, D5*'Conversion rates'!$I$3) -> 29125 | I5: =E5*F5 -> 69.9 | J5: =E5*G5 -> 291250 | L5: 0.1 | M5: 0.07 | N5: 0.05
A6: Celebration | B6: Celebrations | D6: 7 | E6: 5 | F6: =IF(C6>0, C6/'Conversion rates'!$I$3, D6) -> 7 | G6: =IF(C6>0, C6, D6*'Conversion rates'!$I$3) -> 29166.667 | I6: =E6*F6 -> 35 | J6: =E6*G6 -> 145833.33 | L6: 0.3 | M6: 0.2 | N6: 0.15
F7: =IF(C7>0, C7/'Conversion rates'!$I$3, D7) | G7: =IF(C7>0, C7, D7*'Conversion rates'!$I$3) -> 0 | I7: =E7*F7 -> 0 | J7: =E7*G7 -> 0
F8: =IF(C8>0, C8/'Conversion rates'!$I$3, D8) | G8: =IF(C8>0, C8, D8*'Conversion rates'!$I$3) -> 0 | I8: =E8*F8 -> 0 | J8: =E8*G8 -> 0
F9: =IF(C9>0, C9/'Conversion rates'!$I$3, D9) | G9: =IF(C9>0, C9, D9*'Conversion rates'!$I$3) -> 0 | I9: =E9*F9 -> 0 | J9: =E9*G9 -> 0
F10: =IF(C10>0, C10/'Conversion rates'!$I$3, D10) | G10: =IF(C10>0, C10, D10*'Conversion rates'!$I$3) -> 0 | I10: =E10*F10 -> 0 | J10: =E10*G10 -> 0
F11: =IF(C11>0, C11/'Conversion rates'!$I$3, D11) | G11: =IF(C11>0, C11, D11*'Conversion rates'!$I$3) -> 0 | I11: =E11*F11 -> 0 | J11: =E11*G11 -> 0
F12: =IF(C12>0, C12/'Conversion rates'!$I$3, D12) | G12: =IF(C12>0, C12, D12*'Conversion rates'!$I$3) -> 0 | I12: =E12*F12 -> 0 | J12: =E12*G12 -> 0
F13: =IF(C13>0, C13/'Conversion rates'!$I$3, D13) | G13: =IF(C13>0, C13, D13*'Conversion rates'!$I$3) -> 0 | I13: =E13*F13 -> 0 | J13: =E13*G13 -> 0
F14: =IF(C14>0, C14/'Conversion rates'!$I$3, D14) | G14: =IF(C14>0, C14, D14*'Conversion rates'!$I$3) -> 0 | I14: =E14*F14 -> 0 | J14: =E14*G14 -> 0
F15: =IF(C15>0, C15/'Conversion rates'!$I$3, D15) | G15: =IF(C15>0, C15, D15*'Conversion rates'!$I$3) -> 0 | I15: =E15*F15 -> 0 | J15: =E15*G15 -> 0
F16: =IF(C16>0, C16/'Conversion rates'!$I$3, D16) | G16: =IF(C16>0, C16, D16*'Conversion rates'!$I$3) -> 0 | I16: =E16*F16 -> 0 | J16: =E16*G16 -> 0
F17: =IF(C17>0, C17/'Conversion rates'!$I$3, D17) | G17: =IF(C17>0, C17, D17*'Conversion rates'!$I$3) -> 0 | I17: =E17*F17 -> 0 | J17: =E17*G17 -> 0
F18: =IF(C18>0, C18/'Conversion rates'!$I$3, D18) | G18: =IF(C18>0, C18, D18*'Conversion rates'!$I$3) -> 0 | I18: =E18*F18 -> 0 | J18: =E18*G18 -> 0
... F20: =IF(C20>0, C20/'Conversion rates'!$I$3, D20) | G20: =IF(C20>0, C20, D20*'Conversion rates'!$I$3) -> 0 | I20: =E20*F20 -> 0 | J20: =E20*G20 -> 0
F21: =IF(C21>0, C21/'Conversion rates'!$I$3, D21) | G21: =F21*'Conversion rates'!$I$3 -> 0 | I21: =E21*F21 -> 0 | J21: =E21*G21 -> 0
F22: =IF(C22>0, C22/'Conversion rates'!$I$3, D22) | G22: =F22*'Conversion rates'!$I$3 -> 0 | I22: =E22*F22 -> 0 | J22: =E22*G22 -> 0
F23: =IF(C23>0, C23/'Conversion rates'!$I$3, D23) | G23: =F23*'Conversion rates'!$I$3 -> 0 | I23: =E23*F23 -> 0 | J23: =E23*G23 -> 0
F24: =IF(C24>0, C24/'Conversion rates'!$I$3, D24) | G24: =F24*'Conversion rates'!$I$3 -> 0 | I24: =E24*F24 -> 0 | J24: =E24*G24 -> 0
F25: =IF(C25>0, C25/'Conversion rates'!$I$3, D25) | G25: =F25*'Conversion rates'!$I$3 -> 0 | I25: =E25*F25 -> 0 | J25: =E25*G25 -> 0
F26: =IF(C26>0, C26/'Conversion rates'!$I$3, D26) | G26: =F26*'Conversion rates'!$I$3 -> 0 | I26: =E26*F26 -> 0 | J26: =E26*G26 -> 0
F27: =IF(C27>0, C27/'Conversion rates'!$I$3, D27) | G27: =F27*'Conversion rates'!$I$3 -> 0 | I27: =E27*F27 -> 0 | J27: =E27*G27 -> 0
F28: =IF(C28>0, C28/'Conversion rates'!$I$3, D28) | G28: =F28*'Conversion rates'!$I$3 -> 0 | I28: =E28*F28 -> 0 | J28: =E28*G28 -> 0
F29: =IF(C29>0, C29/'Conversion rates'!$I$3, D29) | G29: =F29*'Conversion rates'!$I$3 -> 0 | I29: =E29*F29 -> 0 | J29: =E29*G29 -> 0
F30: =IF(C30>0, C30/'Conversion rates'!$I$3, D30) | G30: =F30*'Conversion rates'!$I$3 -> 0 | I30: =E30*F30 -> 0 | J30: =E30*G30 -> 0
F31: =IF(C31>0, C31/'Conversion rates'!$I$3, D31) | G31: =F31*'Conversion rates'!$I$3 -> 0 | I31: =E31*F31 -> 0 | J31: =E31*G31 -> 0
F32: =IF(C32>0, C32/'Conversion rates'!$I$3, D32) | G32: =F32*'Conversion rates'!$I$3 -> 0 | I32: =E32*F32 -> 0 | J32: =E32*G32 -> 0
... F976: =IF(C976>0, C976/'Conversion rates'!$I$3, D976) | G976: =F976*'Conversion rates'!$I$3 -> 0 | I976: =E976*F976 -> 0 | J976: =E976*G976 -> 0

Sheet Conversion rates
E1: ="Base conversion ( " & E3 & " points = " & G3 & " $ = " & F3 & " coins)" -> Base conversion ( 25000 points = 6 $ = 500 coins)
E2: Points value | F2: Coins | G2: USD | H2: points / coin | I2: points / USD | J2: coins / USD
E3: 25000 | F3: 500 | G3: 6 | H3: =E3/F3 -> 50 | I3: =E3/G3 -> 4166.6667 | J3: =F3/G3 -> 83.333333
C5: Categories
C6: Kit
C7: Pack
C8: Celebration
C9: Original
A17: For reference only. Not used in this model
A19: 1st Party Store | B19: USD | C19: coins | D19: coins rounded incl bonus | E19: value | F19: points value
B20: 5.99 | C20: =B20*$J$3 -> 499.16667 | D20: 500 | E20: =D20/(B20*$J$3) -> 1.0016694 | F20: =B20*$I$3 -> 24958.333 | H20: $5.99 →baseline. no bonus
B21: 9.99 | C21: =B21*$J$3 -> 832.5 | D21: 1000 | E21: =D21/(B21*$J$3) -> 1.2012012 | F21: =B21*$I$3 -> 41625 | H21: $9.99 → (+20%)
B22: 19.99 | C22: =B22*$J$3 -> 1665.8333 | D22: 2050 | E22: =D22/(B22*$J$3) -> 1.2306153 | F22: =B22*$I$3 -> 83291.667 | H22: $19.99 → (+25%) ← decoy
B23: 29.99 | C23: =B23*$J$3 -> 2499.1667 | D23: 3500 | E23: =D23/(B23*$J$3) -> 1.4004668 | F23: =B23*$I$3 -> 124958.33 | H23: $29.99 → (+40%) Best value
B24: 49.99 | C24: =B24*$J$3 -> 4165.8333 | D24: 6500 | E24: =D24/(B24*$J$3) -> 1.5603121 | F24: =B24*$I$3 -> 208291.67 | H24: $49.99 → (+50%)
B25: 99.99 | C25: =B25*$J$3 -> 8332.5 | D25: 14500 | E25: =D25/(B25*$J$3) -> 1.740174 | F25: =B25*$I$3 -> 416625 | H25: $99.99 → (+70%) best bargain
H26: This way the mid-tier ($19.99) looks less attractive compared to $49.99. nudging players upward. and the top tiers feel like a big step up in value.

Sheet Context
B3: PLAN | G3: Context
G4: Provide content plan
A5: done | B5: create and validate model | G5: Set price levels
B6: find points needed in store for each category | G6: Align with BP -> ARPU / month
B7: align ARPPU and ARPU with BP | G7: Standar SKUs. not including promos
B8: break out kits and celebrations to content plan | G8: Not considering marketplace
B9: align store pricing points in USD with GL | G9: Timespan 1 month
G10: Model does not care about which items are SC/HC or HC only wec
G16: Gemeni deep research check
H17: % of total population | I17: Paying % | J17: Gemeni ARRPU
G18: Persona 1: Core FUT (every day) | H18: 0.2 | I18: 0.3 | J18: $25 - $40
G19: Persona 2: Dedicated FUT (2-3 times / week) | H19: 0.35 | I19: 0.15 | J19: $10 - $15
G20: Persona 3: Casual FUT ( a few times / month) | H20: 0.45 | I20: 0.03 | J20: $5 - $10

Sheet Softhard currency comparison
A2: GBP -> USD | B2: 1.34
A3: EUR -> SEK | B3: 9.36
A4: EUR -> USD | B4: 1.17
A5: SEK -> USD | B5: 0.11
A8: League of Legends
A9: Hard currency | B9: EUR | C9: USD | D9: USD/Hard Currency | E9: Discount
A10: 575 | B10: 4.99 | C10: =B10*B$4 -> 5.8383 | D10: =C10/A10 -> 0.010153565 | E10: =(D$10-D10)/D$10 -> 0
A11: 1380 | B11: 10.99 | C11: =B11*B$4 -> 12.8583 | D11: =C11/A11 -> 0.0093176087 | E11: =(D$10-D11)/D$10 -> 0.082331329
A12: 2800 | B12: 21.99 | C12: =B12*B$4 -> 25.7283 | D12: =C12/A12 -> 0.0091886786 | E12: =(D$10-D12)/D$10 -> 0.095029344
A13: 4500 | B13: 34.99 | C13: =B13*B$4 -> 40.9383 | D13: =C13/A13 -> 0.0090974 | E13: =(D$10-D13)/D$10 -> 0.10401915
A14: 6500 | B14: 49.99 | C14: =B14*B$4 -> 58.4883 | D14: =C14/A14 -> 0.0089982 | E14: =(D$10-D14)/D$10 -> 0.11378912
A15: 13500 | B15: 99.99 | C15: =B15*B$4 -> 116.9883 | D15: =C15/A15 -> 0.0086658 | E15: =(D$10-D15)/D$10 -> 0.14652639
A16: 33500 | B16: 244.99 | C16: =B16*B$4 -> 286.6383 | D16: =C16/A16 -> 0.0085563672 | E16: =(D$10-D16)/D$10 -> 0.15730416
A17: 60200 | B17: 429.99 | C17: =B17*B$4 -> 503.0883 | D17: =C17/A17 -> 0.0083569485 | E17: =(D$10-D17)/D$10 -> 0.17694442
A19: Note that League of Legends do not write that more RP = discount, instead they give you "bonus RP", i.e. 13500 RP is 11525 RP + 1975 bonus RP
A22: Apex Legends
A23: Hard currency | B23: EUR | C23: USD | D23: USD/Hard Currency | E23: Discount
A24: 500 | B24: 4.99 | C24: =B24*B$4 -> 5.8383 | D24: =C24/A24 -> 0.0116766 | E24: =(D$24-D24)/D$24 -> 0
A25: 1000 | B25: 9.99 | C25: =B25*B$4 -> 11.6883 | D25: =C25/A25 -> 0.0116883 | E25: =(D$24-D25)/D$24 -> -0.001002004
A26: 2150 | B26: 19.99 | C26: =B26*B$4 -> 23.3883 | D26: =C26/A26 -> 0.010878279 | E26: =(D$24-D26)/D$24 -> 0.068369297
A27: 4350 | B27: 39.99 | C27: =B27*B$4 -> 46.7883 | D27: =C27/A27 -> 0.010755931 | E27: =(D$24-D27)/D$24 -> 0.07884735
A28: 6700 | B28: 59.99 | C28: =B28*B$4 -> 70.1883 | D28: =C28/A28 -> 0.010475866 | E28: =(D$24-D28)/D$24 -> 0.10283253
A29: 11500 | B29: 99.99 | C29: =B29*B$4 -> 116.9883 | D29: =C29/A29 -> 0.010172896 | E29: =(D$24-D29)/D$24 -> 0.1287793
A31: Same as LoL -> bonus coins (i.e 2000 + 150 bonus)
A33: The Finals
A34: Hard currency | B34: EUR | C34: USD | D34: USD/Hard Currency | E34: Discount
A35: 500 | B35: 4.99 | C35: =B35*B$4 -> 5.8383 | D35: =C35/A35 -> 0.0116766 | E35: =(D$24-D35)/D$24 -> 0
A36: 1150 | B36: 9.99 | C36: =B36*B$4 -> 11.6883 | D36: =C36/A36 -> 0.010163739 | E36: =(D$24-D36)/D$24 -> 0.12956347
A37: 2400 | B37: 19.99 | C37: =B37*B$4 -> 23.3883 | D37: =C37/A37 -> 0.009745125 | E37: =(D$24-D37)/D$24 -> 0.16541416
A38: 6250 | B38: 49.99 | C38: =B38*B$4 -> 58.4883 | D38: =C38/A38 -> 0.009358128 | E38: =(D$24-D38)/D$24 -> 0.19855711
A39: 13000 | B39: 99.99 | C39: =B39*B$4 -> 116.9883 | D39: =C39/A39 -> 0.0089991 | E39: =(D$24-D39)/D$24 -> 0.22930476
O40: Indonesian Rupiah (IDR)
A41: EA FC | O41: Indonesia — PlayStation Store (IDR)
A42: Hard currency | B42: SEK | C42: USD | D42: USD/Hard Currency | E42: Discount | O42: Price (IDR)
A43: 100 | B43: 15 | C43: =B43*B$5 -> 1.65 | D43: =C43/A43 -> 0.0165 | E43: =(D$43-D43)/D$43 -> 0 | O43: Rp 16,000
A44: 500 | B44: 65 | C44: =B44*B$5 -> 7.15 | D44: =C44/A44 -> 0.0143 | E44: =(D$43-D44)/D$43 -> 0.13333333 | O44: Rp 77,000
A45: 1050 | B45: 120 | C45: =B45*B$5 -> 13.2 | D45: =C45/A45 -> 0.012571429 | E45: =(D$43-D45)/D$43 -> 0.23809524 | O45: Rp 151,000
A46: 1600 | B46: 180 | C46: =B46*B$5 -> 19.8 | D46: =C46/A46 -> 0.012375 | E46: =(D$43-D46)/D$43 -> 0.25 | O46: Rp 230,000
A47: 2800 | B47: 279 | C47: =B47*B$5 -> 30.69 | D47: =C47/A47 -> 0.010960714 | E47: =(D$43-D47)/D$43 -> 0.33571429 | O47: Rp 380,000
A48: 5900 | B48: 580 | C48: =B48*B$5 -> 63.8 | D48: =C48/A48 -> 0.010813559 | E48: =(D$43-D48)/D$43 -> 0.34463277 | O48: Rp 760,000
...

Sheet Cosmetics comparison other game
B1: League of Legends
B3: HC (RP) | C3: EUR | D3: USD | E3: USD/HC | F3: Skin 1 | G3: Price USD | H3: Skin 2 | I3: Price USD | J3: Skin 3 | K3: Price USD | N3: Fx
B4: 1380 | C4: 10.99 | D4: =C4*O$6 -> 12.8583 | E4: =D4/B4 -> 0.0093176087 | F4: 1350 | G4: =E4*F4 -> 12.578772 | H4: 3250 | I4: =H4*E4 -> 30.282228 | J4: 450 | K4: =J4*E4 -> 4.1929239
B5: 2800 | C5: 21.99 | D5: =C5*O$6 -> 25.7283 | E5: =D5/B5 -> 0.0091886786 | F5: 1350 | G5: =E5*F5 -> 12.404716 | H5: 3250 | I5: =H5*E5 -> 29.863205 | J5: 450 | K5: =J5*E5 -> 4.1349054 | N5: EUR -> SEK | O5: 9.36
B6: 33500 | C6: 244.99 | D6: =C6*O$6 -> 286.6383 | E6: =D6/B6 -> 0.0085563672 | F6: 1350 | G6: =E6*F6 -> 11.551096 | H6: 3250 | I6: =H6*E6 -> 27.808193 | J6: 450 | K6: =J6*E6 -> 3.8503652 | N6: EUR -> USD | O6: 1.17
N7: SEK -> USD | O7: 0.11
B8: Skin 1 | C8: Most common release price for new skins
B9: Skin 2 | C9: Top tier skins. very detailed
B10: Skin 3 | C10: Old skins that are pretty basic and outdated compared to new skins
B13: Fortnite
B14: Dance
B15: HC (V-bucks) | C15: SEK | D15: USD | E15: USD/HC | F15: Dance 1 | G15: Price USD | H15: Dance 2 | I15: Price USD | J15: Dance 3 | K15: Price USD
B16: 2800 | C16: 214.99 | D16: =C16*O$7 -> 23.6489 | E16: =D16/B16 -> 0.0084460357 | F16: 200 | G16: =F16*E16 -> 1.6892071 | H16: 500 | I16: =H16*E16 -> 4.2230179 | J16: 800 | K16: =J16*E16 -> 6.7568286
B17: 5000 | C17: 349.99 | D17: =C17*O$7 -> 38.4989 | E17: =D17/B17 -> 0.00769978 | F17: 200 | G17: =F17*E17 -> 1.539956 | H17: 500 | I17: =H17*E17 -> 3.84989 | J17: 800 | K17: =J17*E17 -> 6.159824
B18: 13500 | C18: 849.99 | D18: =C18*O$7 -> 93.4989 | E18: =D18/B18 -> 0.0069258444 | F18: 200 | G18: =F18*E18 -> 1.3851689 | H18: 500 | I18: =H18*E18 -> 3.4629222 | J18: 800 | K18: =J18*E18 -> 5.5406756
B20: Skin
B21: HC (V-bucks) | C21: SEK | D21: USD | E21: USD/HC | F21: Skin 1 | G21: Price USD | H21: Skin 2 | I21: Price USD | J21: Skin 3 | K21: Price USD
B22: 2800 | C22: 214.99 | D22: =C22*O$7 -> 23.6489 | E22: =D22/B22 -> 0.0084460357 | F22: 1200 | G22: =F22*E22 -> 10.135243 | H22: 1500 | I22: =H22*E22 -> 12.669054 | J22: 1800 | K22: =J22*E22 -> 15.202864
B23: 5000 | C23: 349.99 | D23: =C23*O$7 -> 38.4989 | E23: =D23/B23 -> 0.00769978 | F23: 1200 | G23: =F23*E23 -> 9.239736 | H23: 1500 | I23: =H23*E23 -> 11.54967 | J23: 1800 | K23: =J23*E23 -> 13.859604
B24: 13500 | C24: 849.99 | D24: =C24*O$7 -> 93.4989 | E24: =D24/B24 -> 0.0069258444 | F24: 1200 | G24: =F24*E24 -> 8.3110133 | H24: 1500 | I24: =H24*E24 -> 10.388767 | J24: 1800 | K24: =J24*E24 -> 12.46652
B26: Skin 1 | C26: Dark Tricera Ops - own series skins (ie not external partnership)
B27: Skin 2 | C27: Beavis (from Beavis and Butthead)
B28: Skin 3 | C28: Snoop Dogg
B30: In general skins (or Outfits as they are called in Fortnite) seems to be between 1200-1500 Vbucks regardless of partnership or not
B31: They work with a lot of bundles where you get outfit, emote and dance
B33: Adidas collaboration
B34: HC (V-bucks) | C34: SEK | D34: USD | E34: USD/HC | F34: Skin 1 | G34: Price USD | H34: Skin 2 | I34: Price USD | J34: Skin 3 | K34: Price USD
B35: 2800 | C35: 214.99 | D35: =C35*O$7 -> 23.6489 | E35: =D35/B35 -> 0.0084460357 | F35: 800 | G35: =F35*E35 -> 6.7568286 | H35: 1500 | I35: =H35*E35 -> 12.669054 | J35: 500 | K35: =J35*E35 -> 4.2230179
B36: 5000 | C36: 349.99 | D36: =C36*O$7 -> 38.4989 | E36: =D36/B36 -> 0.00769978 | F36: 800 | G36: =F36*E36 -> 6.159824 | H36: 1500 | I36: =H36*E36 -> 11.54967 | J36: 500 | K36: =J36*E36 -> 3.84989
B37: 13500 | C37: 849.99 | D37: =C37*O$7 -> 93.4989 | E37: =D37/B37 -> 0.0069258444 | F37: 800 | G37: =F37*E37 -> 5.5406756 | H37: 1500 | I37: =H37*E37 -> 10.388767 | J37: 500 | K37: =J37*E37 -> 3.4629222
B39: Skin 1 | C39: Adidas Samba shoe
B40: Skin 2 | C40: Adidas complete outfit
B41: Skin 3 | C41: Dance/emote
B43: Apex Legends
B45: HC (Apec Coins) | C45: EUR | D45: USD | E45: USD/HC | F45: Skin 1 | G45: Price USD | H45: Skin 2 | I45: Price USD | J45: Skin 3 | K45: Price USD
B46: 2150 | C46: 19.99 | D46: =C46*O$6 -> 23.3883 | E46: =D46/B46 -> 0.010878279 | F46: 1800 | G46: =F46*E46 -> 19.580902 | H46: 3000 | I46: =H46*E46 -> 32.634837 | J46: 6000 | K46: =J46*E46 -> 65.269674
B47: 4350 | C47: 39.99 | D47: =C47*O$6 -> 46.7883 | E47: =D47/B47 -> 0.010755931 | F47: 1800 | G47: =F47*E47 -> 19.360676 | H47: 3000 | I47: =H47*E47 -> 32.267793 | J47: 6000 | K47: =J47*E47 -> 64.535586
B48: 6700 | C48: 59.99 | D48: =C48*O$6 -> 70.1883 | E48: =D48/B48 -> 0.010475866 | F48: 1800 | G48: =F48*E48 -> 18.856558 | H48: 3000 | I48: =H48*E48 -> 31.427597 | J48: 6000 | K48: =J48*E48 -> 62.855194
B50: Skin 1 | C50: Kawaii Kitty Wattson - a quite detailed kawaii style skin
B51: Skin 2 | C51: Born of Blood Bundle - character skin + weapon skin + frame + trackers
...

Sheet HARD curr comp console
A2: GBP -> USD | B2: 1.34
A3: EUR -> SEK | B3: 9.36
A4: EUR -> USD | B4: 1.17
A5: SEK -> USD | B5: 0.11
K21: Local Currency | L21: USD Currency | M21: Conversion / PS FX
J22: Hong Kong | K22: 12.6 | L22: 1.39 | M22: =K22/L22 -> 9.0647482
J23: Singapore | K23: 1.9 | L23: 1.39 | M23: =K23/L23 -> 1.3669065
J24: Indonesia | K24: 20300 | L24: 1.39 | M24: =K24/L24 -> 14604.317
O40: Indonesian Rupiah (IDR)
A41: EA FC | C41: This proves you cannot use pure FX conversion to input prices - Local factor is key | H41: PlayStation US Prices | I41: Japan — PlayStation Store (JPY) | J41: 1.26 | K41: 7.82 | L41: 16820 | M41: PlayStation Store (SGD) | N41: Hong Kong — PlayStation Store (HKD) | O41: Indonesia — PlayStation Store (IDR)
A42: Hard currency | B42: SEK | C42: USD | D42: USD/Hard Currency | E42: Discount | G42: FC Points Pack | H42: US Price (USD) | I42: Price (Japanese Yen) | J42: Recalc. Singapore Dollars (SGD) | K42: Recalc. Hongkong Dollars (HKD) | L42: Recalc. Indonesian Rupiah (IDR) | M42: Approx. Singapore Dollars (SGD) | N42: Price (HKD) | O42: Price (IDR)
A43: 100 | B43: 15 | C43: =B43*B$5 -> 1.65 | D43: =C43/A43 -> 0.0165 | E43: =(D$43-D43)/D$43 -> 0 | G43: 100 | H43: 0.99 | I43: ¥150 | J43: =H43*$J$41 -> 1.2474 | K43: =H43*$K$41 -> 7.7418 | L43: =H43*$L$41 -> 16651.8 | M43: SGD 1.60 | N43: HK$ 9 | O43: Rp 16,000
A44: 500 | B44: 65 | C44: =B44*B$5 -> 7.15 | D44: =C44/A44 -> 0.0143 | E44: =(D$43-D44)/D$43 -> 0.13333333 | G44: 500 | H44: 4.99 | I44: ¥690 | J44: =H44*$J$41 -> 6.2874 | K44: =H44*$K$41 -> 39.0218 | L44: =H44*$L$41 -> 83931.8 | M44: SGD 7.60 | N44: HK$ 40 | O44: Rp 77,000
A45: 1050 | B45: 120 | C45: =B45*B$5 -> 13.2 | D45: =C45/A45 -> 0.012571429 | E45: =(D$43-D45)/D$43 -> 0.23809524 | G45: 1 050 | H45: 9.99 | I45: ¥1 400 | J45: =H45*$J$41 -> 12.5874 | K45: =H45*$K$41 -> 78.1218 | L45: =H45*$L$41 -> 168031.8 | M45: SGD 15.00 | N45: HK$ 78 | O45: Rp 151,000
A46: 1600 | B46: 180 | C46: =B46*B$5 -> 19.8 | D46: =C46/A46 -> 0.012375 | E46: =(D$43-D46)/D$43 -> 0.25 | G46: 1 600 | H46: 14.99 | I46: ¥2 100 | J46: =H46*$J$41 -> 18.8874 | K46: =H46*$K$41 -> 117.2218 | L46: =H46*$L$41 -> 252131.8 | M46: SGD 22.00 | N46: HK$ 120 | O46: Rp 230,000
A47: 2800 | B47: 279 | C47: =B47*B$5 -> 30.69 | D47: =C47/A47 -> 0.010960714 | E47: =(D$43-D47)/D$43 -> 0.33571429 | G47: 2 800 | H47: 24.99 | I47: ¥3 400 | J47: =H47*$J$41 -> 31.4874 | K47: =H47*$K$41 -> 195.4218 | L47: =H47*$L$41 -> 420331.8 | M47: SGD 35.54 | N47: HK$ 198 | O47: Rp 380,000
A48: 5900 | B48: 580 | C48: =B48*B$5 -> 63.8 | D48: =C48/A48 -> 0.010813559 | E48: =(D$43-D48)/D$43 -> 0.34463277 | G48: 5 900 | H48: 49.99 | I48: ¥6 600 | J48: =H48*$J$41 -> 62.9874 | K48: =H48*$K$41 -> 390.9218 | L48: =H48*$L$41 -> 840831.8 | M48: SGD 72.00 | N48: HK$ 398 | O48: Rp 760,000
A49: 12000 | B49: 1099 | C49: =B49*B$5 -> 120.89 | D49: =C49/A49 -> 0.010074167 | E49: =(D$43-D49)/D$43 -> 0.38944444 | G49: 12 000 | H49: 99.99 | I49: ¥13 300 | J49: =H49*$J$41 -> 125.9874 | K49: =H49*$K$41 -> 781.9218 | L49: =H49*$L$41 -> 1681831.8 | M49: SGD 140.48 | N49: HK$ 798 | O49: Rp 1,510,000
A50: 18500 | B50: 1649 | C50: =B50*B$5 -> 181.39 | D50: =C50/A50 -> 0.0098048649 | E50: =(D$43-D50)/D$43 -> 0.40576577 | G50: 18 500 | H50: 149.99 | I50: ¥19 900 | J50: =H50*$J$41 -> 188.9874 | K50: =H50*$K$41 -> 1172.9218 | L50: =H50*$L$41 -> 2522831.8 | M50: SGD 212.00 | N50: HK$ 1,180 | O50: Rp 2,260,000
A52: If you have EA Play most coin bundles are 10% off
A55: FC Points Price Comparison — US vs EU vs Japan
A56: Source Links | B56: https://store.playstation.com/en-us/category/2548d67b-59aa-4045-824c-d606e0021672?utm_source=chatgpt.com | C56: https://fifauteam.com/fc-points-prices-fc-26/?utm_source=chatgpt.com | D56: https://store.playstation.com/ja-jp/category/2548d67b-59aa-4045-824c-d606e0021672?utm_source=chatgpt.com
A57: Points Pack | B57: US (USD) | C57: Europe (EUR) | D57: Japan (JPY) | E57: Price (Japanese Yen)
A58: 100 | B58: 0.99 | C58: 0.99 | D58: 150 | E58: ¥150 | F58: =D58/C58 -> 151.51515
A59: 500 | B59: 4.99 | C59: 4.99 | D59: 690 | E59: ¥690 | F59: =D59/C59 -> 138.27655 | H59: =C59/C58 -> 5.040404 | I59: =D59/D58 -> 4.6
A60: 1050 | B60: 9.99 | C60: 9.99 | D60: 1400 | E60: ¥1 400 | F60: =D60/C60 -> 140.14014 | H60: =C60/C59 -> 2.002004 | I60: =D60/D59 -> 2.0289855
A61: 1600 | B61: 14.99 | C61: 14.99 | D61: 2100 | E61: ¥2 100 | F61: =D61/C61 -> 140.0934 | H61: =C61/C60 -> 1.5005005 | I61: =D61/D60 -> 1.5
A62: 2800 | B62: 24.99 | C62: 24.99 | D62: 3400 | E62: ¥3 400 | F62: =D62/C62 -> 136.05442 | H62: =C62/C61 -> 1.6671114 | I62: =D62/D61 -> 1.6190476
A63: 5900 | B63: 49.99 | C63: 49.99 | D63: 6600 | E63: ¥6 600 | F63: =D63/C63 -> 132.02641 | H63: =C63/C62 -> 2.0004002 | I63: =D63/D62 -> 1.9411765
A64: 12000 | B64: 99.99 | C64: 99.99 | D64: 13300 | E64: ¥13 300 | F64: =D64/C64 -> 133.0133 | H64: =C64/C63 -> 2.0002 | I64: =D64/D63 -> 2.0151515
A65: 18500 | B65: 149.99 | C65: 149.99 | D65: 19900 | E65: ¥19 900 | F65: =D65/C65 -> 132.67551 | H65: =C65/C64 -> 1.50005 | I65: =D65/D64 -> 1.4962406

Sheet Hard Currency Pricing
A1: GOALS
A2: Standard Packs | E2: 6
A3: Standard Packs expensive | E3: 20
A4: Kits Internal | E4: 3.99
A5: Kits Partnership | E5: 6.99
A6: Celebrations | E6: 7
A8: Current
A9: Hard currency | D9: USD | E9: USD/Hard Currency | F9: Discount
A10: 5000 | D10: 5.99 | E10: =D10/A10 -> 0.001198 | F10: =(E$10-E10)/E$10 -> 0
A11: 10000 | D11: 9.99 | E11: =D11/A11 -> 0.000999 | F11: =(E$10-E11)/E$10 -> 0.16611018
A12: 20500 | D12: 19.99 | E12: =D12/A12 -> 0.00097512195 | F12: =(E$10-E12)/E$10 -> 0.18604178
A13: 35000 | D13: 29.99 | E13: =D13/A13 -> 0.00085685714 | F13: =(E$10-E13)/E$10 -> 0.28476031
A14: 65000 | D14: 49.99 | E14: =D14/A14 -> 0.00076907692 | F14: =(E$10-E14)/E$10 -> 0.35803262 | I14: =25000/500 -> 50
A15: 145000 | D15: 99.99 | E15: =D15/A15 -> 0.00068958621 | F15: =(E$10-E15)/E$10 -> 0.42438547
A17: Proposal - high discount (56%) | J17: 500 coins | L17: 100 coins
A18: Hard currency | D18: USD | E18: USD/Hard Currency | F18: Discount | G18: Not discounted price | H18: Bonus | I18: Equals soft currency | J18: Price per pack | K18: Packs possible to buy | L18: Price per pack | M18: Packs possible to buy
A19: 100 | D19: 1.59 | E19: =D19/A19 -> 0.0159 | F19: =(E$19-E19)/E$19 -> 0 | G19: 100 | I19: =A19*50 -> 5000 | K19: 0 | L19: =D19 -> 1.59 | M19: =A19/100 -> 1
A20: 500 | D20: 5.99 | E20: =D20/A20 -> 0.01198 | F20: =(E$19-E20)/E$19 -> 0.24654088 | G20: =D20/E$19 -> 376.72956 | H20: 400 + 100 bonus | I20: =A20*50 -> 25000 | J20: 5.99 | K20: =A20/500 -> 1 | L20: =100*E20 -> 1.198 | M20: =A20/100 -> 5
A21: 1000 | D21: 9.99 | E21: =D21/A21 -> 0.00999 | F21: =(E$19-E21)/E$19 -> 0.37169811 | G21: =D21/E$19 -> 628.30189 | H21: 850 + 150 bonus | I21: =A21*50 -> 50000 | J21: =500*E21 -> 4.995 | K21: =A21/500 -> 2 | L21: =100*E21 -> 0.999 | M21: =A21/100 -> 10
A22: 2200 | D22: 19.99 | E22: =D22/A22 -> 0.0090863636 | F22: =(E$19-E22)/E$19 -> 0.42853059 | G22: =D22/E$19 -> 1257.2327 | H22: 1700 + 500 bonus | I22: =A22*50 -> 110000 | J22: =500*E22 -> 4.5431818 | K22: =A22/500 -> 4.4 | L22: =100*E22 -> 0.90863636 | M22: =A22/100 -> 22
A23: 3500 | D23: 29.99 | E23: =D23/A23 -> 0.0085685714 | F23: =(E$19-E23)/E$19 -> 0.46109614 | G23: =D23/E$19 -> 1886.1635 | H23: 2500 + 1000 bonus | I23: =A23*50 -> 175000 | J23: =500*E23 -> 4.2842857 | K23: =A23/500 -> 7 | L23: =100*E23 -> 0.85685714 | M23: =A23/100 -> 35
A24: 6500 | D24: 49.99 | E24: =D24/A24 -> 0.0076907692 | F24: =(E$19-E24)/E$19 -> 0.51630382 | G24: =D24/E$19 -> 3144.0252 | H24: 4000 + 2500 bonus | I24: =A24*50 -> 325000 | J24: =500*E24 -> 3.8453846 | K24: =A24/500 -> 13 | L24: =100*E24 -> 0.76907692 | M24: =A24/100 -> 65
A25: 14500 | D25: 99.99 | E25: =D25/A25 -> 0.0068958621 | F25: =(E$19-E25)/E$19 -> 0.56629798 | G25: =D25/E$19 -> 6288.6792 | H25: 8000 + 6500 bonus | I25: =A25*50 -> 725000 | J25: =500*E25 -> 3.447931 | K25: =A25/500 -> 29 | L25: =100*E25 -> 0.68958621 | M25: =A25/100 -> 145
A27: Proposal - moderate discount (48%)
A28: Hard currency | D28: USD | E28: USD/Hard Currency | F28: Discount | G28: Not discounted price | H28: Bonus
A29: 100 | D29: 1.59 | E29: =D29/A29 -> 0.0159 | F29: =(E$29-E29)/E$29 -> 0 | G29: 100 | I29: =A29*50 -> 5000 | K29: 0 | L29: =100*E29 -> 1.59 | M29: =A29/100 -> 1
A30: 500 | D30: 5.99 | E30: =D30/A30 -> 0.01198 | F30: =(E$29-E30)/E$29 -> 0.24654088 | G30: =D30/E$19 -> 376.72956 | H30: 400 + 100 bonus | I30: =A30*50 -> 25000 | J30: =500*E30 -> 5.99 | K30: =A30/500 -> 1 | L30: =100*E30 -> 1.198 | M30: =A30/100 -> 5
A31: 950 | D31: 9.99 | E31: =D31/A31 -> 0.010515789 | F31: =(E$29-E31)/E$29 -> 0.33862959 | G31: =D31/E$19 -> 628.30189 | H31: 850 + 100 bonus | I31: =A31*50 -> 47500 | J31: =500*E31 -> 5.2578947 | K31: =A31/500 -> 1.9 | L31: =100*E31 -> 1.0515789 | M31: =A31/100 -> 9.5
A32: 2000 | D32: 19.99 | E32: =D32/A32 -> 0.009995 | F32: =(E$29-E32)/E$29 -> 0.37138365 | G32: =D32/E$19 -> 1257.2327 | H32: 1700 + 300 bonus | I32: =A32*50 -> 100000 | J32: =500*E32 -> 4.9975 | K32: =A32/500 -> 4 | L32: =100*E32 -> 0.9995 | M32: =A32/100 -> 20
A33: 3250 | D33: 29.99 | E33: =D33/A33 -> 0.0092276923 | F33: =(E$29-E33)/E$29 -> 0.41964199 | G33: =D33/E$19 -> 1886.1635 | H33: 2500 + 1250 bonus | I33: =A33*50 -> 162500 | J33: =500*E33 -> 4.6138462 | K33: =A33/500 -> 6.5 | L33: =100*E33 -> 0.92276923 | M33: =A33/100 -> 32.5
A34: 5750 | D34: 49.99 | E34: =D34/A34 -> 0.008693913 | F34: =(E$29-E34)/E$29 -> 0.45321302 | G34: =D34/E$19 -> 3144.0252 | H34: 4000 + 2750 bonus | I34: =A34*50 -> 287500 | J34: =500*E34 -> 4.3469565 | K34: =A34/500 -> 11.5 | L34: =100*E34 -> 0.8693913 | M34: =A34/100 -> 57.5
A35: 12000 | D35: 99.99 | E35: =D35/A35 -> 0.0083325 | F35: =(E$29-E35)/E$29 -> 0.4759434 | G35: =D35/E$19 -> 6288.6792 | H35: 8000 + 4000 bonus | I35: =A35*50 -> 600000 | J35: =500*E35 -> 4.16625 | K35: =A35/500 -> 24 | L35: =100*E35 -> 0.83325 | M35: =A35/100 -> 120
A37: Proposal - low discount (30%)
A38: Hard currency | D38: USD | E38: USD/Hard Currency | F38: Discount | G38: Not discounted price | H38: Bonus
A39: 100 | D39: 1.59 | E39: =D39/A39 -> 0.0159 | F39: =(E$39-E39)/E$39 -> 0 | G39: 100 | I39: =A39*50 -> 5000 | K39: 0 | L39: =100*E39 -> 1.59 | M39: =A39/100 -> 1
A40: 400 | D40: 5.99 | E40: =D40/A40 -> 0.014975 | F40: =(E$39-E40)/E$39 -> 0.058176101 | G40: =D40/E$19 -> 376.72956 | H40: 375 + 25 bonus | I40: =A40*50 -> 20000 | J40: =500*E40 -> 7.4875 | K40: =A40/500 -> 0.8 | L40: =100*E40 -> 1.4975 | M40: =A40/100 -> 4
A41: 700 | D41: 9.99 | E41: =D41/A41 -> 0.014271429 | F41: =(E$39-E41)/E$39 -> 0.10242588 | G41: =D41/E$19 -> 628.30189 | H41: 635 + 75 bonus | I41: =A41*50 -> 35000 | J41: =500*E41 -> 7.1357143 | K41: =A41/500 -> 1.4 | L41: =100*E41 -> 1.4271429 | M41: =A41/100 -> 7
A42: 1450 | D42: 19.99 | E42: =D42/A42 -> 0.013786207 | F42: =(E$39-E42)/E$39 -> 0.13294296 | G42: =D42/E$19 -> 1257.2327 | H42: 1250 + 200 bonus | I42: =A42*50 -> 72500 | J42: =500*E42 -> 6.8931034 | K42: =A42/500 -> 2.9 | L42: =100*E42 -> 1.3786207 | M42: =A42/100 -> 14.5
A43: 2250 | D43: 29.99 | E43: =D43/A43 -> 0.013328889 | F43: =(E$39-E43)/E$39 -> 0.1617051 | G43: =D43/E$19 -> 1886.1635 | H43: 1900 + 350 bonus | I43: =A43*50 -> 112500 | J43: =500*E43 -> 6.6644444 | K43: =A43/500 -> 4.5 | L43: =100*E43 -> 1.3328889 | M43: =A43/100 -> 22.5
A44: 4000 | D44: 49.99 | E44: =D44/A44 -> 0.0124975 | F44: =(E$39-E44)/E$39 -> 0.21399371 | G44: =D44/E$19 -> 3144.0252 | H44: 3100 + 900 bonus | I44: =A44*50 -> 200000 | J44: =500*E44 -> 6.24875 | K44: =A44/500 -> 8 | L44: =100*E44 -> 1.24975 | M44: =A44/100 -> 40
...

Sheet Suggestion
B1: USD for North America | C1: USD for North America | D1: EUR | E1: EUR | F1: YEN | G1: YEN | H1: Asia | I1: USD for Asia
A2: Hard currency | B2: Retail Price (USD) | C2: Wholesale price (console) | D2: Retail Price (EUR) | E2: Wholesale price (console) | F2: Retail Price (YEN) | G2: Wholesale price (console) | H2: Retail Price (USD) | I2: Wholesale price (console) | J2: Equals soft currency | K2: Bonus | L2: Cost per coin | M2: Coins / $ | N2: Discount
A3: 380 | B3: 5.99 | C3: 4.19 | D3: 5.99 | E3: 3.49 | F3: 880 | G3: 560 | H3: 4.99 | I3: 3.49 | J3: 19000 | K3: None | L3: =B3/A3 -> 0.015763158 | M3: =A3/B3 -> 63.439065 | N3: 0 | P3: 138.27655
A4: 650 | B4: 9.99 | C4: 6.99 | D4: 9.99 | E4: 5.82 | F4: 1540 | G4: 980 | H4: 9.99 | I4: 6.99 | J4: 32500 | K4: 625 + 25 bonus | L4: =B4/A4 -> 0.015369231 | M4: =A4/B4 -> 65.065065 | N4: =(M4-$M$3)/$M$3 -> 0.025630894 | P4: 140.14014
A5: 1375 | B5: 19.99 | C5: 13.99 | D5: 19.99 | E5: 11.66 | F5: 2860 | G5: 1820 | H5: 19.99 | I5: 13.99 | J5: 68750 | K5: 1250 + 125 bonus | L5: =B5/A5 -> 0.014538182 | M5: =A5/B5 -> 68.784392 | N5: =(M5-$M$3)/$M$3 -> 0.084259235 | P5: 140.0934
A6: 2100 | B6: 29.99 | C6: 20.99 | D6: 29.99 | E6: 17.49 | F6: 4180 | G6: 2660 | H6: 29.99 | I6: 20.99 | J6: 105000 | K6: 1900 + 200 bonus | L6: =B6/A6 -> 0.014280952 | M6: =A6/B6 -> 70.023341 | N6: =(M6-$M$3)/$M$3 -> 0.10378898 | P6: 136.05442
A7: 3750 | B7: 49.99 | C7: 34.99 | D7: 49.99 | E7: 29.16 | F7: 6589 | G7: 4193 | H7: 49.99 | I7: 34.99 | J7: 187500 | K7: 3100 + 650 bonus | L7: =B7/A7 -> 0.013330667 | M7: =A7/B7 -> 75.015003 | N7: =(M7-$M$3)/$M$3 -> 0.18247334 | P7: 132.02641
A8: 7750 | B8: 99.99 | C8: 69.99 | D8: 99.99 | E8: 58.32 | F8: 13310 | G8: 8470 | H8: 99.99 | I8: 69.99 | J8: 387500 | K8: 6000 + 1750 bonus | L8: =B8/A8 -> 0.012901935 | M8: =A8/B8 -> 77.507751 | N8: =(M8-$M$3)/$M$3 -> 0.22176691 | P8: 133.0133
A10: Standard packs (WIP) | B10: Contains | C10: Fair Value | J10: Price (SC) | K10: Hard currency | L10: Supply/user | M10: Price (USD)
A12: Daily Free Pack | B12: 3x Basic+ | C12: 3000 | J12: 0 | K12: 0 | L12: 1 (Daily)
A13: 4 Basic+ Pack | B13: 4x Basic+ | C13: 4000 | J13: 4000 | K13: =J13/50 -> 80 | L13: ∞ | M13: 1.03-1.27 | O13: "Filler pack"
A14: 3 Common+ Pack | B14: 3x Common+ | C14: 7500 | E14: =C3/B3 -> 0.69949917 | J14: 7500 | K14: =J14/50 -> 150 | L14: ∞ | M14: 1.94-2.39 | O14: "Main pack"
A15: 2 Uncommon+ Pack | B15: 2x Uncommon+ | C15: 13000 | E15: =C4/B4 -> 0.6996997 | J15: 13000 | K15: =J15/50 -> 260 | L15: ∞ | M15: 3.35-4.13
A16: 1x Rare+ Pack | B16: 1x Rare+ | C16: 30000 | E16: =C5/B5 -> 0.69984992 | J16: 30000 | K16: =J16/50 -> 600 | L16: ∞ | M16: 7.74-9.54
A17: Mix Pack | B17: 1x Uncommon+, 2x Common+, 3x Basic+ | C17: 12500 | E17: =C6/B6 -> 0.69989997 | J17: 12500 | K17: =J17/50 -> 250 | L17: ∞ | M17: 3.23-3.98
A18: Mix Pack Large | B18: 1x Rare+, 2x Uncommon+, 3x Common+, 4x Basic+ | C18: 54500 | E18: =C7/B7 -> 0.69993999 | J18: 51500 | K18: =J18/50 -> 1030 | L18: ∞ | M18: 13.29-16.38
A19: Mix Pack XL | B19: 2x Rare+, 4x Uncommon+, 6x Common+, 8x Basic+ | C19: 109000 | E19: =C8/B8 -> 0.69997 | J19: 95000 | K19: =J19/50 -> 1900 | L19: ∞ | M19: 24.51-30.21
A21: Time-limited packs (examples) | B21: Contains | C21: Fair Value | J21: Price (SC) | K21: Hard currency | L21: Supply/user | M21: (Price USD)
A23: WC Qualifier Pack | B23: 5x Uncommon+ | C23: 33500 | J23: 29000 | K23: =J23/50 -> 580 | L23: 3 | M23: 7.48-9.22
A24: Samba Pack | B24: 2x Rare+ Brazilian Strikers (ST) | C24: 60000 | J24: 55000 | K24: =J24/50 -> 1100 | L24: 1 | M24: 14.19-17.49
A25: X-mas Present | B25: 3x Basic+, 2x Common+ | C25: 8000 | J25: 0 | K25: =J25/50 -> 0 | L25: 1 | M25: 0
A26: Black Weekend Mega Pack | B26: 5x Rare+, 10x Uncommon+, 15x Common+, 20x Basic+ | C26: 272500 | J26: 199000 | K26: =J26/50 -> 3980 | L26: 5 | M26: 51.35-63.28
A27: Originals Rashford | B27: 1x Rare+ Rashford (stat range guarantees) | C27: 30000 | J27: HC only | K27: 1900 | L27: ∞ | M27: 24.51-30.21
A28: Originals Messi | B28: 1x Epic+ Messi (stat range guarantees) | C28: 250000 | J28: HC only | K28: 4900 | L28: ∞ | M28: 63.22-77.91
A29: Originals KSI | B29: 1x Rare+ KSI (fully randomized stats) | C29: 30000 | J29: HC only | K29: 2200 | L29: ∞ | M29: 28.38-34.98
C34: =C3/1.25 -> 3.352
C35: =C4/1.25 -> 5.592
C36: =C5/1.25 -> 11.192
C37: =C6/1.25 -> 16.792
C38: =C7/1.25 -> 27.992
C39: =C8/1.25 -> 55.992

Sheet Regional Pricing
