Workbook

Sheet Plan
A2: WORK STREAMS | F2: CONCEPT | AS2: PRE-PRODUCTION | CF2: PRODUCTION | GS2: RELEASE | MS2: LIVE SERVICE
F3: GATE 0 | G3: CONCEPT ~2 months Target: T0 Ideation | AS3: GATE 1 | AT3: PRE-PRODUCTION Target: T1-T2 R&D / GDD-TDD-Brief | CF3: GATE 2 | CG3: EARLY PROD Target: T3 Prototype | DS3: GATE 3 | DT3: MID PRO Target: T4 MVP | FF3: GATE 4 | FG3: END PROD Target: T5 Feature Complete | GS3: GATE 5 | GT3: ALPHA Target: T6 Player Tested | IF3: GATE 6 | IG3: BETA Target: T6 Player Tested | JS3: GATE 7 | JT3: LAUNCH Target: T6 Player Ready | LF3: GATE 8 | LG3: FIRST RELEASE ~1.5 months Target: T6-T7 Player Ready / Expand | MS3: GATE 9 | MT3: LS 1 Live Target: T7 Expand | OF3: GATE 10 | OG3: LS 2 Live Target: T8 Scale
A4: Epic | B4: Feature | C4: Size | D4: Current Tier | E4: Notes | G4: CEO | H4: Creative Director | I4: Head of Legal | J4: COO | K4: HR Manager | L4: Executive Producer | M4: Producer | N4: Game Producer | O4: Tech Producer | P4: Art Producer | Q4: Game Director | R4: Game Design Lead | S4: Level Design Lead | T4: Game Designer | U4: Combat Designer | V4: Level Designer | W4: Technical Designer | X4: Writer | Y4: Art Director | Z4: Concept Artist | AA4: UI/UX Designer | AB4: Graphic Designer | AC4: Character Artist | AD4: Environment Artist | AE4: Prop Artist | AF4: Animator | AG4: Character Rigger | AH4: VFX Artist | AI4: Technical Artist | AJ4: CTO | AK4: Tech Lead | AL4: Gameplay Developer | AM4: Full Stack Developer | AN4: Backend Developer | AO4: Network Engineer | AP4: QA | AQ4: Sound Designer | AR4: Platform Team | AT4: CEO | AU4: Creative Director | AV4: Head of Legal | AW4: COO | AX4: HR Manager | AY4: Executive Producer | AZ4: Producer | BA4: Game Producer | BB4: Tech Producer | BC4: Art Producer | BD4: Game Director | BE4: Game Design Lead | BF4: Level Design Lead | BG4: Game Designer | BH4: Combat Designer | BI4: Level Designer | BJ4: Technical Designer | BK4: Writer | BL4: Art Director | BM4: Concept Artist | BN4: UI/UX Designer | BO4: Graphic Designer | BP4: Character Artist | BQ4: Environment Artist | BR4: Prop Artist | BS4: Animator | BT4: Character Rigger | BU4: VFX Artist | BV4: Technical Artist | BW4: CTO | BX4: Tech Lead | BY4: Gameplay Developer | BZ4: Full Stack Developer | CA4: Backend Developer | CB4: Network Engineer | CC4: QA | CD4: Sound Designer | CE4: Platform Team | CG4: CEO | CH4: Creative Director | CI4: Head of Legal | CJ4: COO | CK4: HR Manager | CL4: Executive Producer | CM4: Producer | CN4: Game Producer | CO4: Tech Producer | CP4: Art Producer | CQ4: Game Director | CR4: Game Design Lead | CS4: Level Design Lead | CT4: Game Designer | CU4: Combat Designer | CV4: Level Designer | CW4: Technical Designer | CX4: Writer | CY4: Art Director | CZ4: Concept Artist | DA4: UI/UX Designer | DB4: Graphic Designer | DC4: Character Artist | DD4: Environment Artist | DE4: Prop Artist | DF4: Animator | DG4: Character Rigger | DH4: VFX Artist | DI4: Technical Artist | DJ4: CTO | DK4: Tech Lead | DL4: Gameplay Developer | DM4: Full Stack Developer | DN4: Backend Developer | DO4: Network Engineer | DP4: QA | DQ4: Sound Designer | DR4: Platform Team | DT4: CEO | DU4: Creative Director | DV4: Head of Legal | DW4: COO | DX4: HR Manager | DY4: Executive Producer | DZ4: Producer | EA4: Game Producer | EB4: Tech Producer | EC4: Art Producer | ED4: Game Director | EE4: Game Design Lead | EF4: Level Design Lead | EG4: Game Designer | EH4: Combat Designer | EI4: Level Designer | EJ4: Technical Designer | EK4: Writer | EL4: Art Director | EM4: Concept Artist | EN4: UI/UX Designer | EO4: Graphic Designer | EP4: Character Artist | EQ4: Environment Artist | ER4: Prop Artist | ES4: Animator | ET4: Character Rigger | EU4: VFX Artist | EV4: Technical Artist | EW4: CTO | EX4: Tech Lead | EY4: Gameplay Developer | EZ4: Full Stack Developer | FA4: Backend Developer | FB4: Network Engineer | FC4: QA | FD4: Sound Designer | FE4: Platform Team | FG4: CEO | FH4: Creative Director | FI4: Head of Legal | FJ4: COO | FK4: HR Manager | FL4: Executive Producer | FM4: Producer | FN4: Game Producer | FO4: Tech Producer | FP4: Art Producer | FQ4: Game Director | FR4: Game Design Lead | FS4: Level Design Lead | FT4: Game Designer | FU4: Combat Designer | FV4: Level Designer | FW4: Technical Designer | FX4: Writer | FY4: Art Director | FZ4: Concept Artist | GA4: UI/UX Designer | GB4: Graphic Designer | GC4: Character Artist | GD4: Environment Artist | GE4: Prop Artist | GF4: Animator | GG4: Character Rigger | GH4: VFX Artist | GI4: Technical Artist | GJ4: CTO | GK4: Tech Lead | GL4: Gameplay Developer | GM4: Full Stack Developer | GN4: Backend Developer | GO4: Network Engineer | GP4: QA | GQ4: Sound Designer | GR4: Platform Team | GT4: CEO | GU4: Creative Director | GV4: Head of Legal | GW4: COO | GX4: HR Manager | GY4: Executive Producer | GZ4: Producer | HA4: Game Producer | HB4: Tech Producer | HC4: Art Producer | HD4: Game Director | HE4: Game Design Lead | HF4: Level Design Lead | HG4: Game Designer | HH4: Combat Designer | HI4: Level Designer | HJ4: Technical Designer | HK4: Writer | HL4: Art Director | HM4: Concept Artist | HN4: UI/UX Designer | HO4: Graphic Designer | HP4: Character Artist | HQ4: Environment Artist | HR4: Prop Artist | HS4: Animator | HT4: Character Rigger | HU4: VFX Artist | HV4: Technical Artist | HW4: CTO | HX4: Tech Lead | HY4: Gameplay Developer | HZ4: Full Stack Developer | IA4: Backend Developer | IB4: Network Engineer | IC4: QA | ID4: Sound Designer | IE4: Platform Team | IG4: CEO | IH4: Creative Director | II4: Head of Legal | IJ4: COO | IK4: HR Manager | IL4: Executive Producer | IM4: Producer | IN4: Game Producer | IO4: Tech Producer | IP4: Art Producer | IQ4: Game Director | IR4: Game Design Lead | IS4: Level Design Lead | IT4: Game Designer | IU4: Combat Designer | IV4: Level Designer | IW4: Technical Designer | IX4: Writer | IY4: Art Director | IZ4: Concept Artist | JA4: UI/UX Designer | JB4: Graphic Designer | JC4: Character Artist | JD4: Environment Artist | JE4: Prop Artist | JF4: Animator | JG4: Character Rigger | JH4: VFX Artist | JI4: Technical Artist | JJ4: CTO | JK4: Tech Lead | JL4: Gameplay Developer | JM4: Full Stack Developer | JN4: Backend Developer | JO4: Network Engineer | JP4: QA | JQ4: Sound Designer | JR4: Platform Team | JT4: CEO | JU4: Creative Director | JV4: Head of Legal | JW4: COO | JX4: HR Manager | JY4: Executive Producer | JZ4: Producer | KA4: Game Producer | KB4: Tech Producer | KC4: Art Producer | KD4: Game Director | KE4: Game Design Lead | KF4: Level Design Lead | KG4: Game Designer | KH4: Combat Designer | KI4: Level Designer | KJ4: Technical Designer | KK4: Writer | KL4: Art Director | KM4: Concept Artist | KN4: UI/UX Designer | KO4: Graphic Designer | KP4: Character Artist | KQ4: Environment Artist | KR4: Prop Artist | KS4: Animator | KT4: Character Rigger | KU4: VFX Artist | KV4: Technical Artist | KW4: CTO | KX4: Tech Lead | KY4: Gameplay Developer | KZ4: Full Stack Developer | LA4: Backend Developer | LB4: Network Engineer | LC4: QA | LD4: Sound Designer | LE4: Platform Team | LG4: CEO | LH4: Creative Director | LI4: Head of Legal | LJ4: COO | LK4: HR Manager | LL4: Executive Producer | LM4: Producer | LN4: Game Producer | LO4: Tech Producer | LP4: Art Producer | LQ4: Game Director | LR4: Game Design Lead | LS4: Level Design Lead | LT4: Game Designer | LU4: Combat Designer | LV4: Level Designer | LW4: Technical Designer | LX4: Writer | LY4: Art Director | LZ4: Concept Artist | MA4: UI/UX Designer | MB4: Graphic Designer | MC4: Character Artist | MD4: Environment Artist | ME4: Prop Artist | MF4: Animator | MG4: Character Rigger | MH4: VFX Artist | MI4: Technical Artist | MJ4: CTO | MK4: Tech Lead | ML4: Gameplay Developer | MM4: Full Stack Developer | MN4: Backend Developer | MO4: Network Engineer | MP4: QA | MQ4: Sound Designer | MR4: Platform Team | MT4: CEO | MU4: Creative Director | MV4: Head of Legal | MW4: COO | MX4: HR Manager | MY4: Executive Producer | MZ4: Producer | NA4: Game Producer | NB4: Tech Producer | NC4: Art Producer | ND4: Game Director | NE4: Game Design Lead | NF4: Level Design Lead | NG4: Game Designer | NH4: Combat Designer | NI4: Level Designer | NJ4: Technical Designer | NK4: Writer | NL4: Art Director | NM4: Concept Artist | NN4: UI/UX Designer | NO4: Graphic Designer | NP4: Character Artist | NQ4: Environment Artist | NR4: Prop Artist | NS4: Animator | NT4: Character Rigger | NU4: VFX Artist | NV4: Technical Artist | NW4: CTO | NX4: Tech Lead | NY4: Gameplay Developer | NZ4: Full Stack Developer | OA4: Backend Developer | OB4: Network Engineer | OC4: QA | OD4: Sound Designer | OE4: Platform Team | OG4: CEO | OH4: Creative Director | OI4: Head of Legal | OJ4: COO | OK4: HR Manager | OL4: Executive Producer | OM4: Producer | ON4: Game Producer | OO4: Tech Producer | OP4: Art Producer | OQ4: Game Director | OR4: Game Design Lead | OS4: Level Design Lead | OT4: Game Designer | OU4: Combat Designer | OV4: Level Designer | OW4: Technical Designer | OX4: Writer | OY4: Art Director | OZ4: Concept Artist | PA4: UI/UX Designer | PB4: Graphic Designer | PC4: Character Artist | PD4: Environment Artist | PE4: Prop Artist | PF4: Animator | PG4: Character Rigger | PH4: VFX Artist | PI4: Technical Artist | PJ4: CTO | PK4: Tech Lead | PL4: Gameplay Developer | PM4: Full Stack Developer | PN4: Backend Developer | PO4: Network Engineer | PP4: QA | PQ4: Sound Designer | PR4: Platform Team
A5: Player Build
B6: Player Progression | C6: L | D6: T1: R&D
B7: Skill System | C7: L | D7: T1: R&D
B8: Achievements & Trophies | C8: M | D8: T1: R&D
B9: Factions / Reputation | C9: M | D9: T1: R&D
B10: FTUE | C10: M | D10: T2: GDD/TDD/Brief
B11: Professions | C11: L | D11: T1: R&D
B12: Character Management | C12: M | D12: T0: Ideation
B13: Character Creation & Customization | C13: L | D13: T1: R&D
B14: Garment System | C14: M | D14: T0: Ideation
B15: Persona System | C15: M | D15: T1: R&D
B16: Emote System | C16: S | D16: T0: Ideation
A17: World Systems
B18: Foam Corruption | C18: M | D18: T2: GDD/TDD/Brief
B19: Miasma Corruption | C19: M | D19: T0: Ideation
B20: Water Corruption | C20: M | D20: T0: Ideation
B21: Crystal Corruption | C21: M | D21: T0: Ideation
B22: Time Corruption | C22: M | D22: T0: Ideation
B23: Enemy Corruption | C23: M | D23: T0: Ideation
B24: Oil Corruption | C24: M | D24: T0: Ideation
B25: Texture Corruption | C25: M | D25: T0: Ideation
B26: Environmental Elemental Effects (combination states) | C26: L | D26: T2: GDD/TDD/Brief
B27: Basic Movement System | C27: L | D27: T1: R&D
B28: Advanced Traversal | C28: L | D28: T1: R&D
B29: Navigation | C29: M | D29: T0: Ideation
... B46: Biome - Downtime | C46: M | D46: T4: MVP
A47: Combat
B48: Combat Framework | C48: L | D48: T2: GDD/TDD/Brief
B49: Ranged Combat | C49: M | D49: T0: Ideation
B50: Combat AI Behavior | C50: L | D50: T0: Ideation
B51: Enemies Art | C51: M | D51: T0: Ideation
B52: PvP Combat | C52: L | D52: T0: Ideation
B53: Combat Balance & Telemetry | C53: M | D53: T2: GDD/TDD/Brief
B54: Combat Abilities | C54: L | D54: T1: R&D
B55: Magic | C55: L | D55: T0: Ideation
B56: Full Motion Video (FMV) | C56: M | D56: T1: R&D
A57: User Space
...

Sheet Sheet1
A2: WORK STREAMS | H2: CONCEPT | AU2: PRE-PRODUCTION | CH2: PRODUCTION | GU2: RELEASE | MU2: LIVE SERVICE
H3: GATE 0 | I3: CONCEPT ~2 months Target: T0 Ideation | AU3: GATE 1 | AV3: PRE-PRODUCTION Target: T1-T2 R&D / GDD-TDD-Brief | CH3: GATE 2 | CI3: EARLY PROD Target: T3 Prototype | DU3: GATE 3 | DV3: MID PRO Target: T4 MVP | FH3: GATE 4 | FI3: END PROD Target: T5 Feature Complete | GU3: GATE 5 | GV3: ALPHA Target: T6 Player Tested | IH3: GATE 6 | II3: BETA Target: T6 Player Tested | JU3: GATE 7 | JV3: LAUNCH Target: T6 Player Ready | LH3: GATE 8 | LI3: FIRST RELEASE ~1.5 months Target: T6-T7 Player Ready / Expand | MU3: GATE 9 | MV3: LS 1 Live Target: T7 Expand | OH3: GATE 10 | OI3: LS 2 Live Target: T8 Scale
A4: Epic | B4: Feature | C4: Story | D4: Team | E4: Size | F4: Current Tier | G4: Notes | I4: CEO | J4: Creative Director | K4: Head of Legal | L4: COO | M4: HR Manager | N4: Executive Producer | O4: Producer | P4: Game Producer | Q4: Tech Producer | R4: Art Producer | S4: Game Director | T4: Game Design Lead | U4: Level Design Lead | V4: Game Designer | W4: Combat Designer | X4: Level Designer | Y4: Technical Designer | Z4: Writer | AA4: Art Director | AB4: Concept Artist | AC4: UI/UX Designer | AD4: Graphic Designer | AE4: Character Artist | AF4: Environment Artist | AG4: Prop Artist | AH4: Animator | AI4: Character Rigger | AJ4: VFX Artist | AK4: Technical Artist | AL4: CTO | AM4: Tech Lead | AN4: Gameplay Developer | AO4: Full Stack Developer | AP4: Backend Developer | AQ4: Network Engineer | AR4: QA | AS4: Sound Designer | AT4: Platform Team | AV4: CEO | AW4: Creative Director | AX4: Head of Legal | AY4: COO | AZ4: HR Manager | BA4: Executive Producer | BB4: Producer | BC4: Game Producer | BD4: Tech Producer | BE4: Art Producer | BF4: Game Director | BG4: Game Design Lead | BH4: Level Design Lead | BI4: Game Designer | BJ4: Combat Designer | BK4: Level Designer | BL4: Technical Designer | BM4: Writer | BN4: Art Director | BO4: Concept Artist | BP4: UI/UX Designer | BQ4: Graphic Designer | BR4: Character Artist | BS4: Environment Artist | BT4: Prop Artist | BU4: Animator | BV4: Character Rigger | BW4: VFX Artist | BX4: Technical Artist | BY4: CTO | BZ4: Tech Lead | CA4: Gameplay Developer | CB4: Full Stack Developer | CC4: Backend Developer | CD4: Network Engineer | CE4: QA | CF4: Sound Designer | CG4: Platform Team | CI4: This is the role | CK4: This is the role | CM4: This is the role | CO4: This is the role | CQ4: This is the role | CS4: This is the role | CU4: This is the role | CW4: This is the role | CY4: This is the role | DA4: This is the role | DC4: This is the role | DE4: This is the role | DG4: This is the role | DI4: This is the role | DK4: This is the role | DM4: This is the role | DO4: This is the role | DQ4: This is the role | DS4: This is the role | DV4: CEO | DW4: Creative Director | DX4: Head of Legal | DY4: COO | DZ4: HR Manager | EA4: Executive Producer | EB4: Producer | EC4: Game Producer | ED4: Tech Producer | EE4: Art Producer | EF4: Game Director | EG4: Game Design Lead | EH4: Level Design Lead | EI4: Game Designer | EJ4: Combat Designer | EK4: Level Designer | EL4: Technical Designer | EM4: Writer | EN4: Art Director | EO4: Concept Artist | EP4: UI/UX Designer | EQ4: Graphic Designer | ER4: Character Artist | ES4: Environment Artist | ET4: Prop Artist | EU4: Animator | EV4: Character Rigger | EW4: VFX Artist | EX4: Technical Artist | EY4: CTO | EZ4: Tech Lead | FA4: Gameplay Developer | FB4: Full Stack Developer | FC4: Backend Developer | FD4: Network Engineer | FE4: QA | FF4: Sound Designer | FG4: Platform Team | FI4: CEO | FJ4: Creative Director | FK4: Head of Legal | FL4: COO | FM4: HR Manager | FN4: Executive Producer | FO4: Producer | FP4: Game Producer | FQ4: Tech Producer | FR4: Art Producer | FS4: Game Director | FT4: Game Design Lead | FU4: Level Design Lead | FV4: Game Designer | FW4: Combat Designer | FX4: Level Designer | FY4: Technical Designer | FZ4: Writer | GA4: Art Director | GB4: Concept Artist | GC4: UI/UX Designer | GD4: Graphic Designer | GE4: Character Artist | GF4: Environment Artist | GG4: Prop Artist | GH4: Animator | GI4: Character Rigger | GJ4: VFX Artist | GK4: Technical Artist | GL4: CTO | GM4: Tech Lead | GN4: Gameplay Developer | GO4: Full Stack Developer | GP4: Backend Developer | GQ4: Network Engineer | GR4: QA | GS4: Sound Designer | GT4: Platform Team | GV4: CEO | GW4: Creative Director | GX4: Head of Legal | GY4: COO | GZ4: HR Manager | HA4: Executive Producer | HB4: Producer | HC4: Game Producer | HD4: Tech Producer | HE4: Art Producer | HF4: Game Director | HG4: Game Design Lead | HH4: Level Design Lead | HI4: Game Designer | HJ4: Combat Designer | HK4: Level Designer | HL4: Technical Designer | HM4: Writer | HN4: Art Director | HO4: Concept Artist | HP4: UI/UX Designer | HQ4: Graphic Designer | HR4: Character Artist | HS4: Environment Artist | HT4: Prop Artist | HU4: Animator | HV4: Character Rigger | HW4: VFX Artist | HX4: Technical Artist | HY4: CTO | HZ4: Tech Lead | IA4: Gameplay Developer | IB4: Full Stack Developer | IC4: Backend Developer | ID4: Network Engineer | IE4: QA | IF4: Sound Designer | IG4: Platform Team | II4: CEO | IJ4: Creative Director | IK4: Head of Legal | IL4: COO | IM4: HR Manager | IN4: Executive Producer | IO4: Producer | IP4: Game Producer | IQ4: Tech Producer | IR4: Art Producer | IS4: Game Director | IT4: Game Design Lead | IU4: Level Design Lead | IV4: Game Designer | IW4: Combat Designer | IX4: Level Designer | IY4: Technical Designer | IZ4: Writer | JA4: Art Director | JB4: Concept Artist | JC4: UI/UX Designer | JD4: Graphic Designer | JE4: Character Artist | JF4: Environment Artist | JG4: Prop Artist | JH4: Animator | JI4: Character Rigger | JJ4: VFX Artist | JK4: Technical Artist | JL4: CTO | JM4: Tech Lead | JN4: Gameplay Developer | JO4: Full Stack Developer | JP4: Backend Developer | JQ4: Network Engineer | JR4: QA | JS4: Sound Designer | JT4: Platform Team | JV4: CEO | JW4: Creative Director | JX4: Head of Legal | JY4: COO | JZ4: HR Manager | KA4: Executive Producer | KB4: Producer | KC4: Game Producer | KD4: Tech Producer | KE4: Art Producer | KF4: Game Director | KG4: Game Design Lead | KH4: Level Design Lead | KI4: Game Designer | KJ4: Combat Designer | KK4: Level Designer | KL4: Technical Designer | KM4: Writer | KN4: Art Director | KO4: Concept Artist | KP4: UI/UX Designer | KQ4: Graphic Designer | KR4: Character Artist | KS4: Environment Artist | KT4: Prop Artist | KU4: Animator | KV4: Character Rigger | KW4: VFX Artist | KX4: Technical Artist | KY4: CTO | KZ4: Tech Lead | LA4: Gameplay Developer | LB4: Full Stack Developer | LC4: Backend Developer | LD4: Network Engineer | LE4: QA | LF4: Sound Designer | LG4: Platform Team | LI4: CEO | LJ4: Creative Director | LK4: Head of Legal | LL4: COO | LM4: HR Manager | LN4: Executive Producer | LO4: Producer | LP4: Game Producer | LQ4: Tech Producer | LR4: Art Producer | LS4: Game Director | LT4: Game Design Lead | LU4: Level Design Lead | LV4: Game Designer | LW4: Combat Designer | LX4: Level Designer | LY4: Technical Designer | LZ4: Writer | MA4: Art Director | MB4: Concept Artist | MC4: UI/UX Designer | MD4: Graphic Designer | ME4: Character Artist | MF4: Environment Artist | MG4: Prop Artist | MH4: Animator | MI4: Character Rigger | MJ4: VFX Artist | MK4: Technical Artist | ML4: CTO | MM4: Tech Lead | MN4: Gameplay Developer | MO4: Full Stack Developer | MP4: Backend Developer | MQ4: Network Engineer | MR4: QA | MS4: Sound Designer | MT4: Platform Team | MV4: CEO | MW4: Creative Director | MX4: Head of Legal | MY4: COO | MZ4: HR Manager | NA4: Executive Producer | NB4: Producer | NC4: Game Producer | ND4: Tech Producer | NE4: Art Producer | NF4: Game Director | NG4: Game Design Lead | NH4: Level Design Lead | NI4: Game Designer | NJ4: Combat Designer | NK4: Level Designer | NL4: Technical Designer | NM4: Writer | NN4: Art Director | NO4: Concept Artist | NP4: UI/UX Designer | NQ4: Graphic Designer | NR4: Character Artist | NS4: Environment Artist | NT4: Prop Artist | NU4: Animator | NV4: Character Rigger | NW4: VFX Artist | NX4: Technical Artist | NY4: CTO | NZ4: Tech Lead | OA4: Gameplay Developer | OB4: Full Stack Developer | OC4: Backend Developer | OD4: Network Engineer | OE4: QA | OF4: Sound Designer | OG4: Platform Team | OI4: CEO | OJ4: Creative Director | OK4: Head of Legal | OL4: COO | OM4: HR Manager | ON4: Executive Producer | OO4: Producer | OP4: Game Producer | OQ4: Tech Producer | OR4: Art Producer | OS4: Game Director | OT4: Game Design Lead | OU4: Level Design Lead | OV4: Game Designer | OW4: Combat Designer | OX4: Level Designer | OY4: Technical Designer | OZ4: Writer | PA4: Art Director | PB4: Concept Artist | PC4: UI/UX Designer | PD4: Graphic Designer | PE4: Character Artist | PF4: Environment Artist | PG4: Prop Artist | PH4: Animator | PI4: Character Rigger | PJ4: VFX Artist | PK4: Technical Artist | PL4: CTO | PM4: Tech Lead | PN4: Gameplay Developer | PO4: Full Stack Developer | PP4: Backend Developer | PQ4: Network Engineer | PR4: QA | PS4: Sound Designer | PT4: Platform Team
A5: This is the epic
CI6: Min | CJ6: Max | CK6: Min | CL6: Max | CM6: Min | CN6: Max | CO6: Min | CP6: Max | CQ6: Min | CR6: Max | CS6: Min | CT6: Max | CU6: Min | CV6: Max | CW6: Min | CX6: Max | CY6: Min | CZ6: Max | DA6: Min | DB6: Max | DC6: Min | DD6: Max | DE6: Min | DF6: Max | DG6: Min | DH6: Max | DI6: Min | DJ6: Max | DK6: Min | DL6: Max | DM6: Min | DN6: Max | DO6: Min | DP6: Max | DQ6: Min | DR6: Max | DS6: Min | DT6: Max
B7: This is the feature name | D7: This is the department | This is the team | E7: S | F7: T2: GDD/TDD/Brief | CI7: 3 | CJ7: 6 | CK7: 3 | CL7: 6 | CM7: 3 | CN7: 6 | CO7: 3 | CP7: 6 | CQ7: 3 | CR7: 6 | CS7: 3 | CT7: 6 | CU7: 3 | CV7: 6 | CW7: 3 | CX7: 6 | CY7: 3 | CZ7: 6 | DA7: 3 | DB7: 6 | DC7: 3 | DD7: 6 | DE7: 3 | DF7: 6 | DG7: 3 | DH7: 6 | DI7: 3 | DJ7: 6 | DK7: 3 | DL7: 6 | DM7: 3 | DN7: 6 | DO7: 3 | DP7: 6 | DQ7: 3 | DR7: 6 | DS7: 3 | DT7: 6
C8: This is the story name | D8: This is the department | This is the team | E8: M | F8: T1: R&D | CI8: 12 | CJ8: 20 | CK8: 12 | CL8: 20 | CM8: 12 | CN8: 20 | CO8: 12 | CP8: 20 | CQ8: 12 | CR8: 20 | CS8: 12 | CT8: 20 | CU8: 12 | CV8: 20 | CW8: 12 | CX8: 20 | CY8: 12 | CZ8: 20 | DA8: 12 | DB8: 20 | DC8: 12 | DD8: 20 | DE8: 12 | DF8: 20 | DG8: 12 | DH8: 20 | DI8: 12 | DJ8: 20 | DK8: 12 | DL8: 20 | DM8: 12 | DN8: 20 | DO8: 12 | DP8: 20 | DQ8: 12 | DR8: 20 | DS8: 12 | DT8: 20
C9: This is the story name | D9: This is the department | This is the team | E9: L | F9: T4: MVP | CI9: 11 | CJ9: 15 | CK9: 11 | CL9: 15 | CM9: 11 | CN9: 15 | CO9: 11 | CP9: 15 | CQ9: 11 | CR9: 15 | CS9: 11 | CT9: 15 | CU9: 11 | CV9: 15 | CW9: 11 | CX9: 15 | CY9: 11 | CZ9: 15 | DA9: 11 | DB9: 15 | DC9: 11 | DD9: 15 | DE9: 11 | DF9: 15 | DG9: 11 | DH9: 15 | DI9: 11 | DJ9: 15 | DK9: 11 | DL9: 15 | DM9: 11 | DN9: 15 | DO9: 11 | DP9: 15 | DQ9: 11 | DR9: 15 | DS9: 11 | DT9: 15
C10: This is the story name | D10: This is the department | This is the team | CI10: 5 | CJ10: 7 | CK10: 5 | CL10: 7 | CM10: 5 | CN10: 7 | CO10: 5 | CP10: 7 | CQ10: 5 | CR10: 7 | CS10: 5 | CT10: 7 | CU10: 5 | CV10: 7 | CW10: 5 | CX10: 7 | CY10: 5 | CZ10: 7 | DA10: 5 | DB10: 7 | DC10: 5 | DD10: 7 | DE10: 5 | DF10: 7 | DG10: 5 | DH10: 7 | DI10: 5 | DJ10: 7 | DK10: 5 | DL10: 7 | DM10: 5 | DN10: 7 | DO10: 5 | DP10: 7 | DQ10: 5 | DR10: 7 | DS10: 5 | DT10: 7
B11: This is the feature name | D11: This is the department | This is the team | CI11: 7 | CJ11: 14 | CK11: 7 | CL11: 14 | CM11: 7 | CN11: 14 | CO11: 7 | CP11: 14 | CQ11: 7 | CR11: 14 | CS11: 7 | CT11: 14 | CU11: 7 | CV11: 14 | CW11: 7 | CX11: 14 | CY11: 7 | CZ11: 14 | DA11: 7 | DB11: 14 | DC11: 7 | DD11: 14 | DE11: 7 | DF11: 14 | DG11: 7 | DH11: 14 | DI11: 7 | DJ11: 14 | DK11: 7 | DL11: 14 | DM11: 7 | DN11: 14 | DO11: 7 | DP11: 14 | DQ11: 7 | DR11: 14 | DS11: 7 | DT11: 14
C12: This is the story name | D12: This is the department | This is the team | CI12: 9 | CJ12: 11 | CK12: 9 | CL12: 11 | CM12: 9 | CN12: 11 | CO12: 9 | CP12: 11 | CQ12: 9 | CR12: 11 | CS12: 9 | CT12: 11 | CU12: 9 | CV12: 11 | CW12: 9 | CX12: 11 | CY12: 9 | CZ12: 11 | DA12: 9 | DB12: 11 | DC12: 9 | DD12: 11 | DE12: 9 | DF12: 11 | DG12: 9 | DH12: 11 | DI12: 9 | DJ12: 11 | DK12: 9 | DL12: 11 | DM12: 9 | DN12: 11 | DO12: 9 | DP12: 11 | DQ12: 9 | DR12: 11 | DS12: 9 | DT12: 11
B13: This is the feature name | D13: This is the department | This is the team | CI13: 2 | CJ13: 4 | CK13: 2 | CL13: 4 | CM13: 2 | CN13: 4 | CO13: 2 | CP13: 4 | CQ13: 2 | CR13: 4 | CS13: 2 | CT13: 4 | CU13: 2 | CV13: 4 | CW13: 2 | CX13: 4 | CY13: 2 | CZ13: 4 | DA13: 2 | DB13: 4 | DC13: 2 | DD13: 4 | DE13: 2 | DF13: 4 | DG13: 2 | DH13: 4 | DI13: 2 | DJ13: 4 | DK13: 2 | DL13: 4 | DM13: 2 | DN13: 4 | DO13: 2 | DP13: 4 | DQ13: 2 | DR13: 4 | DS13: 2 | DT13: 4
C14: This is the story name | D14: This is the department | This is the team | CI14: 5.1428571 | CJ14: 7.4285714 | CK14: 5.1428571 | CL14: 7.4285714 | CM14: 5.1428571 | CN14: 7.4285714 | CO14: 5.1428571 | CP14: 7.4285714 | CQ14: 5.1428571 | CR14: 7.4285714 | CS14: 5.1428571 | CT14: 7.4285714 | CU14: 5.1428571 | CV14: 7.4285714 | CW14: 5.1428571 | CX14: 7.4285714 | CY14: 5.1428571 | CZ14: 7.4285714 | DA14: 5.1428571 | DB14: 7.4285714 | DC14: 5.1428571 | DD14: 7.4285714 | DE14: 5.1428571 | DF14: 7.4285714 | DG14: 5.1428571 | DH14: 7.4285714 | DI14: 5.1428571 | DJ14: 7.4285714 | DK14: 5.1428571 | DL14: 7.4285714 | DM14: 5.1428571 | DN14: 7.4285714 | DO14: 5.1428571 | DP14: 7.4285714 | DQ14: 5.1428571 | DR14: 7.4285714 | DS14: 5.1428571 | DT14: 7.4285714
B15: This is the feature name | D15: This is the department | This is the team | CI15: 4.6785714 | CJ15: 6.5357143 | CK15: 4.6785714 | CL15: 6.5357143 | CM15: 4.6785714 | CN15: 6.5357143 | CO15: 4.6785714 | CP15: 6.5357143 | CQ15: 4.6785714 | CR15: 6.5357143 | CS15: 4.6785714 | CT15: 6.5357143 | CU15: 4.6785714 | CV15: 6.5357143 | CW15: 4.6785714 | CX15: 6.5357143 | CY15: 4.6785714 | CZ15: 6.5357143 | DA15: 4.6785714 | DB15: 6.5357143 | DC15: 4.6785714 | DD15: 6.5357143 | DE15: 4.6785714 | DF15: 6.5357143 | DG15: 4.6785714 | DH15: 6.5357143 | DI15: 4.6785714 | DJ15: 6.5357143 | DK15: 4.6785714 | DL15: 6.5357143 | DM15: 4.6785714 | DN15: 6.5357143 | DO15: 4.6785714 | DP15: 6.5357143 | DQ15: 4.6785714 | DR15: 6.5357143 | DS15: 4.6785714 | DT15: 6.5357143
C16: This is the story name | D16: This is the department | This is the team | CI16: 4.2142857 | CJ16: 5.6428571 | CK16: 4.2142857 | CL16: 5.6428571 | CM16: 4.2142857 | CN16: 5.6428571 | CO16: 4.2142857 | CP16: 5.6428571 | CQ16: 4.2142857 | CR16: 5.6428571 | CS16: 4.2142857 | CT16: 5.6428571 | CU16: 4.2142857 | CV16: 5.6428571 | CW16: 4.2142857 | CX16: 5.6428571 | CY16: 4.2142857 | CZ16: 5.6428571 | DA16: 4.2142857 | DB16: 5.6428571 | DC16: 4.2142857 | DD16: 5.6428571 | DE16: 4.2142857 | DF16: 5.6428571 | DG16: 4.2142857 | DH16: 5.6428571 | DI16: 4.2142857 | DJ16: 5.6428571 | DK16: 4.2142857 | DL16: 5.6428571 | DM16: 4.2142857 | DN16: 5.6428571 | DO16: 4.2142857 | DP16: 5.6428571 | DQ16: 4.2142857 | DR16: 5.6428571 | DS16: 4.2142857 | DT16: 5.6428571
B17: This is the feature name | D17: This is the department | This is the team | CI17: 3.75 | CJ17: 4.75 | CK17: 3.75 | CL17: 4.75 | CM17: 3.75 | CN17: 4.75 | CO17: 3.75 | CP17: 4.75 | CQ17: 3.75 | CR17: 4.75 | CS17: 3.75 | CT17: 4.75 | CU17: 3.75 | CV17: 4.75 | CW17: 3.75 | CX17: 4.75 | CY17: 3.75 | CZ17: 4.75 | DA17: 3.75 | DB17: 4.75 | DC17: 3.75 | DD17: 4.75 | DE17: 3.75 | DF17: 4.75 | DG17: 3.75 | DH17: 4.75 | DI17: 3.75 | DJ17: 4.75 | DK17: 3.75 | DL17: 4.75 | DM17: 3.75 | DN17: 4.75 | DO17: 3.75 | DP17: 4.75 | DQ17: 3.75 | DR17: 4.75 | DS17: 3.75 | DT17: 4.75
C18: This is the story name | D18: This is the department | This is the team | CI18: 3.2857143 | CJ18: 3.8571429 | CK18: 3.2857143 | CL18: 3.8571429 | CM18: 3.2857143 | CN18: 3.8571429 | CO18: 3.2857143 | CP18: 3.8571429 | CQ18: 3.2857143 | CR18: 3.8571429 | CS18: 3.2857143 | CT18: 3.8571429 | CU18: 3.2857143 | CV18: 3.8571429 | CW18: 3.2857143 | CX18: 3.8571429 | CY18: 3.2857143 | CZ18: 3.8571429 | DA18: 3.2857143 | DB18: 3.8571429 | DC18: 3.2857143 | DD18: 3.8571429 | DE18: 3.2857143 | DF18: 3.8571429 | DG18: 3.2857143 | DH18: 3.8571429 | DI18: 3.2857143 | DJ18: 3.8571429 | DK18: 3.2857143 | DL18: 3.8571429 | DM18: 3.2857143 | DN18: 3.8571429 | DO18: 3.2857143 | DP18: 3.8571429 | DQ18: 3.2857143 | DR18: 3.8571429 | DS18: 3.2857143 | DT18: 3.8571429
D19: This is the department | This is the team | CI19: 2.8214286 | CJ19: 2.9642857 | CK19: 2.8214286 | CL19: 2.9642857 | CM19: 2.8214286 | CN19: 2.9642857 | CO19: 2.8214286 | CP19: 2.9642857 | CQ19: 2.8214286 | CR19: 2.9642857 | CS19: 2.8214286 | CT19: 2.9642857 | CU19: 2.8214286 | CV19: 2.9642857 | CW19: 2.8214286 | CX19: 2.9642857 | CY19: 2.8214286 | CZ19: 2.9642857 | DA19: 2.8214286 | DB19: 2.9642857 | DC19: 2.8214286 | DD19: 2.9642857 | DE19: 2.8214286 | DF19: 2.9642857 | DG19: 2.8214286 | DH19: 2.9642857 | DI19: 2.8214286 | DJ19: 2.9642857 | DK19: 2.8214286 | DL19: 2.9642857 | DM19: 2.8214286 | DN19: 2.9642857 | DO19: 2.8214286 | DP19: 2.9642857 | DQ19: 2.8214286 | DR19: 2.9642857 | DS19: 2.8214286 | DT19: 2.9642857

Sheet Summary
A1: Epic | B1: Features | C1: Concept ~2 months T0 | D1: Pre-production ~4 months T1-T2 | E1: Early Prod ~4 months T3 | F1: Mid Prod ~6 months T4 | G1: End Prod ~4 months T5 | H1: Alpha ~2 months T6 | I1: Beta ~1.5 months T6 | J1: Launch ~1 month T6 | K1: First Release ~1.5 months T6-T7 | L1: LS 1 Live T7 | M1: LS 2 Live T8 | N1: Total PW
A2: Player Build | B2: 11 | C2: =SUM(Plan!G6:AR16) -> 0 | D2: =SUM(Plan!AT6:CE16) -> 0 | E2: =SUM(Plan!CG6:DR16) -> 0 | F2: =SUM(Plan!DT6:FE16) -> 0 | G2: =SUM(Plan!FG6:GR16) -> 0 | H2: =SUM(Plan!GT6:IE16) -> 0 | I2: =SUM(Plan!IG6:JR16) -> 0 | J2: =SUM(Plan!JT6:LE16) -> 0 | K2: =SUM(Plan!LG6:MR16) -> 0 | L2: =SUM(Plan!MT6:OE16) -> 0 | M2: =SUM(Plan!OG6:PR16) -> 0 | N2: =SUM(C2:M2) -> 0
A3: World Systems | B3: 29 | C3: =SUM(Plan!G18:AR46) -> 0 | D3: =SUM(Plan!AT18:CE46) -> 0 | E3: =SUM(Plan!CG18:DR46) -> 0 | F3: =SUM(Plan!DT18:FE46) -> 0 | G3: =SUM(Plan!FG18:GR46) -> 0 | H3: =SUM(Plan!GT18:IE46) -> 0 | I3: =SUM(Plan!IG18:JR46) -> 0 | J3: =SUM(Plan!JT18:LE46) -> 0 | K3: =SUM(Plan!LG18:MR46) -> 0 | L3: =SUM(Plan!MT18:OE46) -> 0 | M3: =SUM(Plan!OG18:PR46) -> 0 | N3: =SUM(C3:M3) -> 0
A4: Combat | B4: 9 | C4: =SUM(Plan!G48:AR56) -> 0 | D4: =SUM(Plan!AT48:CE56) -> 0 | E4: =SUM(Plan!CG48:DR56) -> 0 | F4: =SUM(Plan!DT48:FE56) -> 0 | G4: =SUM(Plan!FG48:GR56) -> 0 | H4: =SUM(Plan!GT48:IE56) -> 0 | I4: =SUM(Plan!IG48:JR56) -> 0 | J4: =SUM(Plan!JT48:LE56) -> 0 | K4: =SUM(Plan!LG48:MR56) -> 0 | L4: =SUM(Plan!MT48:OE56) -> 0 | M4: =SUM(Plan!OG48:PR56) -> 0 | N4: =SUM(C4:M4) -> 0
A5: User Space | B5: 8 | C5: =SUM(Plan!G58:AR65) -> 0 | D5: =SUM(Plan!AT58:CE65) -> 0 | E5: =SUM(Plan!CG58:DR65) -> 0 | F5: =SUM(Plan!DT58:FE65) -> 0 | G5: =SUM(Plan!FG58:GR65) -> 0 | H5: =SUM(Plan!GT58:IE65) -> 0 | I5: =SUM(Plan!IG58:JR65) -> 0 | J5: =SUM(Plan!JT58:LE65) -> 0 | K5: =SUM(Plan!LG58:MR65) -> 0 | L5: =SUM(Plan!MT58:OE65) -> 0 | M5: =SUM(Plan!OG58:PR65) -> 0 | N5: =SUM(C5:M5) -> 0
A6: Items & Inventory | B6: 9 | C6: =SUM(Plan!G67:AR75) -> 0 | D6: =SUM(Plan!AT67:CE75) -> 0 | E6: =SUM(Plan!CG67:DR75) -> 0 | F6: =SUM(Plan!DT67:FE75) -> 0 | G6: =SUM(Plan!FG67:GR75) -> 0 | H6: =SUM(Plan!GT67:IE75) -> 0 | I6: =SUM(Plan!IG67:JR75) -> 0 | J6: =SUM(Plan!JT67:LE75) -> 0 | K6: =SUM(Plan!LG67:MR75) -> 0 | L6: =SUM(Plan!MT67:OE75) -> 0 | M6: =SUM(Plan!OG67:PR75) -> 0 | N6: =SUM(C6:M6) -> 0
A7: Player Economy | B7: 7 | C7: =SUM(Plan!G77:AR83) -> 0 | D7: =SUM(Plan!AT77:CE83) -> 0 | E7: =SUM(Plan!CG77:DR83) -> 0 | F7: =SUM(Plan!DT77:FE83) -> 0 | G7: =SUM(Plan!FG77:GR83) -> 0 | H7: =SUM(Plan!GT77:IE83) -> 0 | I7: =SUM(Plan!IG77:JR83) -> 0 | J7: =SUM(Plan!JT77:LE83) -> 0 | K7: =SUM(Plan!LG77:MR83) -> 0 | L7: =SUM(Plan!MT77:OE83) -> 0 | M7: =SUM(Plan!OG77:PR83) -> 0 | N7: =SUM(C7:M7) -> 0
A8: Quest System | B8: 12 | C8: =SUM(Plan!G85:AR96) -> 0 | D8: =SUM(Plan!AT85:CE96) -> 0 | E8: =SUM(Plan!CG85:DR96) -> 0 | F8: =SUM(Plan!DT85:FE96) -> 0 | G8: =SUM(Plan!FG85:GR96) -> 0 | H8: =SUM(Plan!GT85:IE96) -> 0 | I8: =SUM(Plan!IG85:JR96) -> 0 | J8: =SUM(Plan!JT85:LE96) -> 0 | K8: =SUM(Plan!LG85:MR96) -> 0 | L8: =SUM(Plan!MT85:OE96) -> 0 | M8: =SUM(Plan!OG85:PR96) -> 0 | N8: =SUM(C8:M8) -> 0
A9: Social & Multiplayer | B9: 10 | C9: =SUM(Plan!G98:AR107) -> 0 | D9: =SUM(Plan!AT98:CE107) -> 0 | E9: =SUM(Plan!CG98:DR107) -> 0 | F9: =SUM(Plan!DT98:FE107) -> 0 | G9: =SUM(Plan!FG98:GR107) -> 0 | H9: =SUM(Plan!GT98:IE107) -> 0 | I9: =SUM(Plan!IG98:JR107) -> 0 | J9: =SUM(Plan!JT98:LE107) -> 0 | K9: =SUM(Plan!LG98:MR107) -> 0 | L9: =SUM(Plan!MT98:OE107) -> 0 | M9: =SUM(Plan!OG98:PR107) -> 0 | N9: =SUM(C9:M9) -> 0
A10: Game Bibles | B10: 6 | C10: =SUM(Plan!G109:AR114) -> 0 | D10: =SUM(Plan!AT109:CE114) -> 0 | E10: =SUM(Plan!CG109:DR114) -> 0 | F10: =SUM(Plan!DT109:FE114) -> 0 | G10: =SUM(Plan!FG109:GR114) -> 0 | H10: =SUM(Plan!GT109:IE114) -> 0 | I10: =SUM(Plan!IG109:JR114) -> 0 | J10: =SUM(Plan!JT109:LE114) -> 0 | K10: =SUM(Plan!LG109:MR114) -> 0 | L10: =SUM(Plan!MT109:OE114) -> 0 | M10: =SUM(Plan!OG109:PR114) -> 0 | N10: =SUM(C10:M10) -> 0
A11: Platform | B11: 19 | C11: =SUM(Plan!G116:AR134) -> 0 | D11: =SUM(Plan!AT116:CE134) -> 0 | E11: =SUM(Plan!CG116:DR134) -> 0 | F11: =SUM(Plan!DT116:FE134) -> 0 | G11: =SUM(Plan!FG116:GR134) -> 0 | H11: =SUM(Plan!GT116:IE134) -> 0 | I11: =SUM(Plan!IG116:JR134) -> 0 | J11: =SUM(Plan!JT116:LE134) -> 0 | K11: =SUM(Plan!LG116:MR134) -> 0 | L11: =SUM(Plan!MT116:OE134) -> 0 | M11: =SUM(Plan!OG116:PR134) -> 0 | N11: =SUM(C11:M11) -> 0
A12: Live Game | B12: 7 | C12: =SUM(Plan!G136:AR142) -> 0 | D12: =SUM(Plan!AT136:CE142) -> 0 | E12: =SUM(Plan!CG136:DR142) -> 0 | F12: =SUM(Plan!DT136:FE142) -> 0 | G12: =SUM(Plan!FG136:GR142) -> 0 | H12: =SUM(Plan!GT136:IE142) -> 0 | I12: =SUM(Plan!IG136:JR142) -> 0 | J12: =SUM(Plan!JT136:LE142) -> 0 | K12: =SUM(Plan!LG136:MR142) -> 0 | L12: =SUM(Plan!MT136:OE142) -> 0 | M12: =SUM(Plan!OG136:PR142) -> 0 | N12: =SUM(C12:M12) -> 0
A13: Partner Build | B13: 8 | C13: =SUM(Plan!G144:AR151) -> 0 | D13: =SUM(Plan!AT144:CE151) -> 0 | E13: =SUM(Plan!CG144:DR151) -> 0 | F13: =SUM(Plan!DT144:FE151) -> 0 | G13: =SUM(Plan!FG144:GR151) -> 0 | H13: =SUM(Plan!GT144:IE151) -> 0 | I13: =SUM(Plan!IG144:JR151) -> 0 | J13: =SUM(Plan!JT144:LE151) -> 0 | K13: =SUM(Plan!LG144:MR151) -> 0 | L13: =SUM(Plan!MT144:OE151) -> 0 | M13: =SUM(Plan!OG144:PR151) -> 0 | N13: =SUM(C13:M13) -> 0
A14: Product Publishing | B14: 7 | C14: =SUM(Plan!G153:AR159) -> 0 | D14: =SUM(Plan!AT153:CE159) -> 0 | E14: =SUM(Plan!CG153:DR159) -> 0 | F14: =SUM(Plan!DT153:FE159) -> 0 | G14: =SUM(Plan!FG153:GR159) -> 0 | H14: =SUM(Plan!GT153:IE159) -> 0 | I14: =SUM(Plan!IG153:JR159) -> 0 | J14: =SUM(Plan!JT153:LE159) -> 0 | K14: =SUM(Plan!LG153:MR159) -> 0 | L14: =SUM(Plan!MT153:OE159) -> 0 | M14: =SUM(Plan!OG153:PR159) -> 0 | N14: =SUM(C14:M14) -> 0
A16: GRAND TOTAL | C16: =SUM(C2:C15) -> 0 | D16: =SUM(D2:D15) -> 0 | E16: =SUM(E2:E15) -> 0 | F16: =SUM(F2:F15) -> 0 | G16: =SUM(G2:G15) -> 0 | H16: =SUM(H2:H15) -> 0 | I16: =SUM(I2:I15) -> 0 | J16: =SUM(J2:J15) -> 0 | ... N16: =SUM(N2:N15) -> 0

Sheet Epics & Features
A1: Epic | B1: Feature | C1: Sizing | D1: Current Tier
A2: Player Build | B2: Player Progression | C2: L | D2: T1: R&D
A3: Player Build | B3: Skill System | C3: L | D3: T1: R&D
A4: Player Build | B4: Achievements & Trophies | C4: M | D4: T1: R&D
A5: Player Build | B5: Factions / Reputation | C5: M | D5: T1: R&D
A6: Player Build | B6: FTUE | C6: M | D6: T2: GDD/TDD/Brief
A7: Player Build | B7: Professions | C7: L | D7: T1: R&D
A8: Player Build | B8: Character Management | C8: M | D8: T0: Ideation
A9: Player Build | B9: Character Creation & Customization | C9: L | D9: T1: R&D
A10: Player Build | B10: Garment System | C10: M | D10: T0: Ideation
A11: Player Build | B11: Persona System | C11: M | D11: T1: R&D
A12: Player Build | B12: Emote System | C12: S | D12: T0: Ideation
... A143: Product Publishing | B143: 3rd-party Store Publishing | C143: M | D143: T0: Ideation

Sheet Roles
A1: Role | B1: Discipline | C1: Notes
A2: CEO | B2: Leadership
A3: Creative Director | B3: Leadership
A4: Head of Legal | B4: Leadership
A5: COO | B5: Leadership
A6: HR Manager | B6: Leadership
A7: Executive Producer | B7: Production
A8: Producer | B8: Production
A9: Game Producer | B9: Production
A10: Tech Producer | B10: Production
A11: Art Producer | B11: Production
A12: Game Director | B12: Design
A13: Game Design Lead | B13: Design
... A39: Platform Team | B39: Platform

Sheet Gates
A1: Gate | B1: Phase | D1: Target Tier | E1: Tier Name | F1: Notes
A2: 0 | B2: Concept | D2: T0 | E2: Ideation | F2: Y-doc, pitch, vision lock; all features captured at T0
A3: 1 | B3: Pre-production | D3: T1-T2 | E3: R&D / GDD-TDD-Brief | F3: GDD/TDD/Art briefs for all greenlit features (T2)
A4: 2 | B4: Early Prod | D4: T3 | E4: Prototype | F4: Prototype every feature; many bugs allowed (T3)
A5: 3 | B5: Mid Prod | D5: T4 | E5: MVP | F5: Full MVP scope - heaviest production gate (T4)
A6: 4 | B6: End Prod | D6: T5 | E6: Feature Complete | F6: Feature complete, polish to ship quality (T5)
A7: 5 | B7: Alpha | D7: T6 | E7: Player Tested | F7: Playtest, telemetry, balance pass; gating bugs only
A8: 6 | B8: Beta | D8: T6 | E8: Player Tested | F8: External player feedback, cert prep, content lock
A9: 7 | B9: Launch | D9: T6 | E9: Player Ready | F9: Day-0 readiness, marketing, store, support
A10: 8 | B10: First Release | D10: T6-T7 | E10: Player Ready / Expand | F10: Live monitoring, hotfixes, day-1/7/30 patches
A11: 9 | B11: LS 1 | D11: T7 | E11: Expand | F11: Expansions, new content drops, season cadence (T7)
A12: 10 | B12: LS 2 | D12: T8 | E12: Scale | F12: Optimize / scale post-load, sustain plan (T8)

Sheet Tiers
A1: Tier | B1: Name | C1: Definition
A2: T0 | B2: Ideation | C2: Idea captured, no commitment
A3: T1 | B3: R&D | C3: Research, prototyping intent, technical feasibility
A4: T2 | B4: GDD / TDD / Brief ready | C4: GDD done, TDD done, art brief done
A5: T3 | B5: Prototype | C5: Functional with no skins, can be bugged
A6: T4 | B6: MVP | C6: Limited quality, but full-featured
A7: T5 | B7: Feature Complete (at quality) | C7: Final assets, polished, no scope cuts left
A8: T6 | B8: Player Ready / Tested | C8: Playtest, alpha, beta, telemetry feedback applied
A9: T7 | B9: Expand | C9: Add to feature / content
A10: T8 | B10: Scale | C10: Productional optimization post-load

Sheet Legend
A1: Cell Color / Section | B1: Meaning
B2: Phase super-headers (row 1 of Plan)
A3: Concept | B3: Concept gate (T0 Ideation)
A4: Pre-production | B4: Pre-production gate (T1-T2)
A5: Production | B5: Early / Mid / End Prod gates (T3-T5)
A6: Release | B6: Alpha / Beta / Launch / First Release
A7: Live Service | B7: LS 1 / LS 2
A9: Discipline | B9: Role group color (row 3 of Plan)
A10: Leadership | B10: CEO, Head of Legal, Head of Finance & Ops, HR Manager
A11: Production | B11: Executive / Producer / Game / Tech / Art Producer
A12: Design | B12: Game Director, Design Leads, Designers, Writer
A13: Art | B13: Art Director, Concept, UI/UX, Character/Env/Prop, Anim, Rig, VFX, TA
A14: Engineering | B14: CTO, Tech Lead, Gameplay/Full Stack/Backend/Network
A15: QA | B15: QA
... A17: Platform | B17: Platform Team
A19: Sizing key (col C)
A20: S | B20: Small feature
A21: M | B21: Medium feature
A22: L | B22: Large feature
A24: How to use
A25: Plan sheet | B25: Fill in man-days per (feature, gate, role). Cells are blank by default.
A26: Totals row | B26: Bottom of Plan: SUMs each role column per gate.
A27: Headcount row | B27: Total PW / (gate months * 20 working days). Edit GATE_MONTHS in the script if your durations change.
A28: Summary sheet | B28: Auto-rolls up Plan totals per epic per gate.
A29: Adding rows | B29: Insert rows inside an epic block on Plan. Update Total PW SUM ranges if you extend past the current last data row.
