Workbook

Sheet Plan
A2: WORK STREAMS | F2: CONCEPT | AS2: PRE-PRODUCTION | CF2: PRODUCTION | IE2: RELEASE | OE2: LIVE SERVICE
F3: GATE 0 | G3: CONCEPT ~2 months Target: T0 Ideation | AS3: GATE 1 | AT3: PRE-PRODUCTION Target: T1-T2 R&D / GDD-TDD-Brief | CF3: GATE 2 | CG3: EARLY PROD Target: T3 Prototype | FE3: GATE 3 | FF3: MID PRO Target: T4 MVP | GR3: GATE 4 | GS3: END PROD Target: T5 Feature Complete | IE3: GATE 5 | IF3: ALPHA Target: T6 Player Tested | JR3: GATE 6 | JS3: BETA Target: T6 Player Tested | LE3: GATE 7 | LF3: LAUNCH Target: T6 Player Ready | MR3: GATE 8 | MS3: FIRST RELEASE ~1.5 months Target: T6-T7 | OE3: GATE 9 | OF3: LS 1 Live Target: T7 Expand | PR3: GATE 10 | PS3: LS 2 Live Target: T8 Scale
A4: Epic | B4: Feature | C4: Size | D4: Current Tier | E4: Notes | G4: CEO | H4: Creative Director | I4: Head of Legal | J4: COO | K4: HR Manager | L4: Executive Producer | M4: Producer | N4: Game Producer | O4: Tech Producer | P4: Art Producer | Q4: Game Director | R4: Game Design Lead | S4: Level Design Lead | T4: Game Designer | U4: Combat Designer | V4: Level Designer | W4: Technical Designer | X4: Writer | Y4: Art Director | Z4: Concept Artist | AA4: UI/UX Designer | AB4: Graphic Designer | AC4: Character Artist | AD4: Environment Artist | AE4: Prop Artist | AF4: Animator | AG4: Character Rigger | AH4: VFX Artist | AI4: Technical Artist | AJ4: CTO | AK4: Tech Lead | AL4: Gameplay Developer | AM4: Full Stack Developer | AN4: Backend Developer | AO4: Network Engineer | AP4: QA | AQ4: Sound Designer | AR4: Platform Team | AT4: CEO | AU4: Creative Director | AV4: Head of Legal | AW4: COO | AX4: HR Manager | AY4: Executive Producer | AZ4: Producer | BA4: Game Producer | BB4: Tech Producer | BC4: Art Producer | BD4: Game Director | BE4: Game Design Lead | BF4: Level Design Lead | BG4: Game Designer | BH4: Combat Designer | BI4: Level Designer | BJ4: Technical Designer | BK4: Writer | BL4: Art Director | BM4: Concept Artist | BN4: UI/UX Designer | BO4: Graphic Designer | BP4: Character Artist | BQ4: Environment Artist | BR4: Prop Artist | BS4: Animator | BT4: Character Rigger | BU4: VFX Artist | BV4: Technical Artist | BW4: CTO | BX4: Tech Lead | BY4: Gameplay Developer | BZ4: Full Stack Developer | CA4: Backend Developer | CB4: Network Engineer | CC4: QA | CD4: Sound Designer | CE4: Platform Team | CG4: CEO Min | CH4: CEO Max | CI4: Creative Director Min | CJ4: Creative Director Max | CK4: Head of Legal Min | CL4: Head of Legal Max | CM4: COO Min | CN4: COO Max | CO4: HR Manager Min | CP4: HR Manager Max | CQ4: Executive Producer Min | CR4: Executive Producer Max | CS4: Producer Min | CT4: Producer Max | CU4: Game Producer Min | CV4: Game Producer Max | CW4: Tech Producer Min | CX4: Tech Producer Max | CY4: Art Producer Min | CZ4: Art Producer Max | DA4: Game Director Min | DB4: Game Director Max | DC4: Game Design Lead Min | DD4: Game Design Lead Max | DE4: Level Design Lead Min | DF4: Level Design Lead Max | DG4: Game Designer Min | DH4: Game Designer Max | DI4: Combat Designer Min | DJ4: Combat Designer Max | DK4: Level Designer Min | DL4: Level Designer Max | DM4: Technical Designer Min | DN4: Technical Designer Max | DO4: Writer Min | DP4: Writer Max | DQ4: Art Director Min | DR4: Art Director Max | DS4: Concept Artist Min | DT4: Concept Artist Max | DU4: UI/UX Designer Min | DV4: UI/UX Designer Max | DW4: Graphic Designer Min | DX4: Graphic Designer Max | DY4: Character Artist Min | DZ4: Character Artist Max | EA4: Environment Artist Min | EB4: Environment Artist Max | EC4: Prop Artist Min | ED4: Prop Artist Max | EE4: Animator Min | EF4: Animator Max | EG4: Character Rigger Min | EH4: Character Rigger Max | EI4: VFX Artist Min | EJ4: VFX Artist Max | EK4: Technical Artist Min | EL4: Technical Artist Max | EM4: CTO Min | EN4: CTO Max | EO4: Tech Lead Min | EP4: Tech Lead Max | EQ4: Gameplay Developer Min | ER4: Gameplay Developer Max | ES4: Full Stack Developer Min | ET4: Full Stack Developer Max | EU4: Backend Developer Min | EV4: Backend Developer Max | EW4: Network Engineer Min | EX4: Network Engineer Max | EY4: QA Min | EZ4: QA Max | FA4: Sound Designer Min | FB4: Sound Designer Max | FC4: Platform Team Min | FD4: Platform Team Max | FF4: CEO | FG4: Creative Director | FH4: Head of Legal | FI4: COO | FJ4: HR Manager | FK4: Executive Producer | FL4: Producer | FM4: Game Producer | FN4: Tech Producer | FO4: Art Producer | FP4: Game Director | FQ4: Game Design Lead | FR4: Level Design Lead | FS4: Game Designer | FT4: Combat Designer | FU4: Level Designer | FV4: Technical Designer | FW4: Writer | FX4: Art Director | FY4: Concept Artist | FZ4: UI/UX Designer | GA4: Graphic Designer | GB4: Character Artist | GC4: Environment Artist | GD4: Prop Artist | GE4: Animator | GF4: Character Rigger | GG4: VFX Artist | GH4: Technical Artist | GI4: CTO | GJ4: Tech Lead | GK4: Gameplay Developer | GL4: Full Stack Developer | GM4: Backend Developer | GN4: Network Engineer | GO4: QA | GP4: Sound Designer | GQ4: Platform Team | GS4: CEO | GT4: Creative Director | GU4: Head of Legal | GV4: COO | GW4: HR Manager | GX4: Executive Producer | GY4: Producer | GZ4: Game Producer | HA4: Tech Producer | HB4: Art Producer | HC4: Game Director | HD4: Game Design Lead | HE4: Level Design Lead | HF4: Game Designer | HG4: Combat Designer | HH4: Level Designer | HI4: Technical Designer | HJ4: Writer | HK4: Art Director | HL4: Concept Artist | HM4: UI/UX Designer | HN4: Graphic Designer | HO4: Character Artist | HP4: Environment Artist | HQ4: Prop Artist | HR4: Animator | HS4: Character Rigger | HT4: VFX Artist | HU4: Technical Artist | HV4: CTO | HW4: Tech Lead | HX4: Gameplay Developer | HY4: Full Stack Developer | HZ4: Backend Developer | IA4: Network Engineer | IB4: QA | IC4: Sound Designer | ID4: Platform Team | IF4: CEO | IG4: Creative Director | IH4: Head of Legal | II4: COO | IJ4: HR Manager | IK4: Executive Producer | IL4: Producer | IM4: Game Producer | IN4: Tech Producer | IO4: Art Producer | IP4: Game Director | IQ4: Game Design Lead | IR4: Level Design Lead | IS4: Game Designer | IT4: Combat Designer | IU4: Level Designer | IV4: Technical Designer | IW4: Writer | IX4: Art Director | IY4: Concept Artist | IZ4: UI/UX Designer | JA4: Graphic Designer | JB4: Character Artist | JC4: Environment Artist | JD4: Prop Artist | JE4: Animator | JF4: Character Rigger | JG4: VFX Artist | JH4: Technical Artist | JI4: CTO | JJ4: Tech Lead | JK4: Gameplay Developer | JL4: Full Stack Developer | JM4: Backend Developer | JN4: Network Engineer | JO4: QA | JP4: Sound Designer | JQ4: Platform Team | JS4: CEO | JT4: Creative Director | JU4: Head of Legal | JV4: COO | JW4: HR Manager | JX4: Executive Producer | JY4: Producer | JZ4: Game Producer | KA4: Tech Producer | KB4: Art Producer | KC4: Game Director | KD4: Game Design Lead | KE4: Level Design Lead | KF4: Game Designer | KG4: Combat Designer | KH4: Level Designer | KI4: Technical Designer | KJ4: Writer | KK4: Art Director | KL4: Concept Artist | KM4: UI/UX Designer | KN4: Graphic Designer | KO4: Character Artist | KP4: Environment Artist | KQ4: Prop Artist | KR4: Animator | KS4: Character Rigger | KT4: VFX Artist | KU4: Technical Artist | KV4: CTO | KW4: Tech Lead | KX4: Gameplay Developer | KY4: Full Stack Developer | KZ4: Backend Developer | LA4: Network Engineer | LB4: QA | LC4: Sound Designer | LD4: Platform Team | LF4: CEO | LG4: Creative Director | LH4: Head of Legal | LI4: COO | LJ4: HR Manager | LK4: Executive Producer | LL4: Producer | LM4: Game Producer | LN4: Tech Producer | LO4: Art Producer | LP4: Game Director | LQ4: Game Design Lead | LR4: Level Design Lead | LS4: Game Designer | LT4: Combat Designer | LU4: Level Designer | LV4: Technical Designer | LW4: Writer | LX4: Art Director | LY4: Concept Artist | LZ4: UI/UX Designer | MA4: Graphic Designer | MB4: Character Artist | MC4: Environment Artist | MD4: Prop Artist | ME4: Animator | MF4: Character Rigger | MG4: VFX Artist | MH4: Technical Artist | MI4: CTO | MJ4: Tech Lead | MK4: Gameplay Developer | ML4: Full Stack Developer | MM4: Backend Developer | MN4: Network Engineer | MO4: QA | MP4: Sound Designer | MQ4: Platform Team | MS4: CEO | MT4: Creative Director | MU4: Head of Legal | MV4: COO | MW4: HR Manager | MX4: Executive Producer | MY4: Producer | MZ4: Game Producer | NA4: Tech Producer | NB4: Art Producer | NC4: Game Director | ND4: Game Design Lead | NE4: Level Design Lead | NF4: Game Designer | NG4: Combat Designer | NH4: Level Designer | NI4: Technical Designer | NJ4: Writer | NK4: Art Director | NL4: Concept Artist | NM4: UI/UX Designer | NN4: Graphic Designer | NO4: Character Artist | NP4: Environment Artist | NQ4: Prop Artist | NR4: Animator | NS4: Character Rigger | NT4: VFX Artist | NU4: Technical Artist | NV4: CTO | NW4: Tech Lead | NX4: Gameplay Developer | NY4: Full Stack Developer | NZ4: Backend Developer | OA4: Network Engineer | OB4: QA | OC4: Sound Designer | OD4: Platform Team | OF4: CEO | OG4: Creative Director | OH4: Head of Legal | OI4: COO | OJ4: HR Manager | OK4: Executive Producer | OL4: Producer | OM4: Game Producer | ON4: Tech Producer | OO4: Art Producer | OP4: Game Director | OQ4: Game Design Lead | OR4: Level Design Lead | OS4: Game Designer | OT4: Combat Designer | OU4: Level Designer | OV4: Technical Designer | OW4: Writer | OX4: Art Director | OY4: Concept Artist | OZ4: UI/UX Designer | PA4: Graphic Designer | PB4: Character Artist | PC4: Environment Artist | PD4: Prop Artist | PE4: Animator | PF4: Character Rigger | PG4: VFX Artist | PH4: Technical Artist | PI4: CTO | PJ4: Tech Lead | PK4: Gameplay Developer | PL4: Full Stack Developer | PM4: Backend Developer | PN4: Network Engineer | PO4: QA | PP4: Sound Designer | PQ4: Platform Team | PS4: CEO | PT4: Creative Director | PU4: Head of Legal | PV4: COO | PW4: HR Manager | PX4: Executive Producer | PY4: Producer | PZ4: Game Producer | QA4: Tech Producer | QB4: Art Producer | QC4: Game Director | QD4: Game Design Lead | QE4: Level Design Lead | QF4: Game Designer | QG4: Combat Designer | QH4: Level Designer | QI4: Technical Designer | QJ4: Writer | QK4: Art Director | QL4: Concept Artist | QM4: UI/UX Designer | QN4: Graphic Designer | QO4: Character Artist | QP4: Environment Artist | QQ4: Prop Artist | QR4: Animator | QS4: Character Rigger | QT4: VFX Artist | QU4: Technical Artist | QV4: CTO | QW4: Tech Lead | QX4: Gameplay Developer | QY4: Full Stack Developer | QZ4: Backend Developer | RA4: Network Engineer | RB4: QA | RC4: Sound Designer | RD4: Platform Team
A5: Player Build
B6: Garment System | C6: M | D6: T0: Ideation | E6: Design / Game design | DG6: 7 | DH6: 10 | DU6: 20 | DV6: 20 | EK6: 10 | EL6: 10 | EQ6: 60 | ER6: 60
B7: Equiment Concepts | E7: Art / Concept Art
B8: Equipment Concepts | E8: Art / Concept Art
B9: Equipment Models | E9: Art / Character Art
B10: Garment Type SFX | E10: Audio / Audio | FA10: 2 | FB10: 3
B11: Equipment Stats integrated with character stats | E11: Engineering / Gameplay Engineering | EQ11: 2 | ER11: 3
B12: Equipment QA | E12: QA / QA
B13: Garment System QA | E13: QA / QA
B14: Garment System GDD/TDD | E14: Design / Game design | DG14: 4 | DH14: 7
B15: Vertical Slice garments | E15: Design / Game design | DG15: 5 | DH15: 5
B16: Garment System Integration | E16: Engineering / Gameplay Engineering
B17: Equip and unequped based on garment system | E17: Engineering / Gameplay Engineering | EQ17: 2 | ER17: 3
B18: Garment System UI | E18: Art / UX/UI | DU18: 10 | DV18: 14
B19: Player equips clothing
B20: Cull occluded body parts | E20: Art / TechArt
B21: Equipment QA | E21: QA / QA
B22: Freeze cloth sim | E22: Art / Animation & Rigging | EE22: 3 | EF22: 5
B23: Garment System QA | E23: QA / QA
B24: Maya tool to represent cloth sim like unreal | E24: Art / Animation & Rigging | EE24: 10 | EF24: 15
B25: Move socket based on clothing type | E25: Art / Animation & Rigging | EE25: 5 | EF25: 10
B26: Setup budget for skining and cloth sim | E26: Art / Animation & Rigging | EE26: 5 | EF26: 7
B27: Setup capsules for cloth collision on character | E27: Art / Animation & Rigging | EE27: 1 | EF27: 2
B28: In-game Tutorial | E28: Design / Game design | DG28: 16 | DH28: 16 | DS28: 5 | DT28: 5 | DU28: 5 | DV28: 5 | EA28: 15 | EB28: 15 | EE28: 5 | EF28: 5 | EI28: 12 | EJ28: 12 | EK28: 10 | EL28: 10 | EQ28: 15 | ER28: 15 | FA28: 2 | FB28: 2
B29: Controls UI | E29: Art / UX/UI | DU29: 2 | DV29: 4
B30: Controls UI | E30: Art / VFX
B31: Narrative | E31: Design / Narrative | DO31: 0.5 | DP31: 1
B32: Tutorial QA check | E32: QA / QA
B33: Tutorial cave contents | E33: Design / Game design | DG33: 1 | DH33: 2
B34: Tutorial Cave Layout Fixes | E34: Design / Level design | DK34: 7 | DL34: 10
B35: Tutorial Cave lighting | E35: Art / Environment Art
B36: Tutorial Configuration/set up/texts | E36: Design / Game design | DG36: 2 | DH36: 3
B37: Tutorial UI | E37: Art / UX/UI | DU37: 4 | DV37: 6
B38: Tutorial VFX | E38: Art / VFX
B39: Tutorial cave Ambience & SFX | E39: Audio / Audio | FA39: 5 | FB39: 7
B40: Tutorial cave set dressing fixes | E40: Art / Environment Art
B41: Player Progression | C41: L | D41: T1: R&D | E41: Design / Game design | DG41: 7 | DH41: 7 | DU41: 3 | DV41: 3 | EI41: 2 | EJ41: 2 | EQ41: 20 | ER41: 20 | FA41: 2 | FB41: 2
...

Sheet Summary
A1: Epic | B1: Features | C1: Concept ~2 months T0 | D1: Pre-production ~4 months T1-T2 | E1: Early Prod ~4 months T3 | F1: Mid Prod ~6 months T4 | G1: End Prod ~4 months T5 | H1: Alpha ~2 months T6 | I1: Beta ~1.5 months T6 | J1: Launch ~1 month T6 | K1: First Release ~1.5 months T6-T7 | L1: LS 1 Live T7 | M1: LS 2 Live T8 | N1: Total PW
A2: Player Build | B2: 11 | C2: =SUM(Plan!G6:AR16) | D2: =SUM(Plan!AT6:CE16) | E2: =SUM(Plan!CG6:DR16) | F2: =SUM(Plan!DT6:FE16) | G2: =SUM(Plan!FG6:GR16) | H2: =SUM(Plan!GT6:IE16) | I2: =SUM(Plan!IG6:JR16) | J2: =SUM(Plan!JT6:LE16) | K2: =SUM(Plan!LG6:MR16) | L2: =SUM(Plan!MT6:OE16) | M2: =SUM(Plan!OG6:PR16) | N2: =SUM(C2:M2)
A3: World Systems | B3: 29 | C3: =SUM(Plan!G18:AR46) | D3: =SUM(Plan!AT18:CE46) | E3: =SUM(Plan!CG18:DR46) | F3: =SUM(Plan!DT18:FE46) | G3: =SUM(Plan!FG18:GR46) | H3: =SUM(Plan!GT18:IE46) | I3: =SUM(Plan!IG18:JR46) | J3: =SUM(Plan!JT18:LE46) | K3: =SUM(Plan!LG18:MR46) | L3: =SUM(Plan!MT18:OE46) | M3: =SUM(Plan!OG18:PR46) | N3: =SUM(C3:M3)
A4: Combat | B4: 9 | C4: =SUM(Plan!G48:AR56) | D4: =SUM(Plan!AT48:CE56) | E4: =SUM(Plan!CG48:DR56) | F4: =SUM(Plan!DT48:FE56) | G4: =SUM(Plan!FG48:GR56) | H4: =SUM(Plan!GT48:IE56) | I4: =SUM(Plan!IG48:JR56) | J4: =SUM(Plan!JT48:LE56) | K4: =SUM(Plan!LG48:MR56) | L4: =SUM(Plan!MT48:OE56) | M4: =SUM(Plan!OG48:PR56) | N4: =SUM(C4:M4)
A5: User Space | B5: 8 | C5: =SUM(Plan!G58:AR65) | D5: =SUM(Plan!AT58:CE65) | E5: =SUM(Plan!CG58:DR65) | F5: =SUM(Plan!DT58:FE65) | G5: =SUM(Plan!FG58:GR65) | H5: =SUM(Plan!GT58:IE65) | I5: =SUM(Plan!IG58:JR65) | J5: =SUM(Plan!JT58:LE65) | K5: =SUM(Plan!LG58:MR65) | L5: =SUM(Plan!MT58:OE65) | M5: =SUM(Plan!OG58:PR65) | N5: =SUM(C5:M5)
A6: Items & Inventory | B6: 9 | C6: =SUM(Plan!G67:AR75) | D6: =SUM(Plan!AT67:CE75) | E6: =SUM(Plan!CG67:DR75) | F6: =SUM(Plan!DT67:FE75) | G6: =SUM(Plan!FG67:GR75) | H6: =SUM(Plan!GT67:IE75) | I6: =SUM(Plan!IG67:JR75) | J6: =SUM(Plan!JT67:LE75) | K6: =SUM(Plan!LG67:MR75) | L6: =SUM(Plan!MT67:OE75) | M6: =SUM(Plan!OG67:PR75) | N6: =SUM(C6:M6)
A7: Player Economy | B7: 7 | C7: =SUM(Plan!G77:AR83) | D7: =SUM(Plan!AT77:CE83) | E7: =SUM(Plan!CG77:DR83) | F7: =SUM(Plan!DT77:FE83) | G7: =SUM(Plan!FG77:GR83) | H7: =SUM(Plan!GT77:IE83) | I7: =SUM(Plan!IG77:JR83) | J7: =SUM(Plan!JT77:LE83) | K7: =SUM(Plan!LG77:MR83) | L7: =SUM(Plan!MT77:OE83) | M7: =SUM(Plan!OG77:PR83) | N7: =SUM(C7:M7)
A8: Quest System | B8: 12 | C8: =SUM(Plan!G85:AR96) | D8: =SUM(Plan!AT85:CE96) | E8: =SUM(Plan!CG85:DR96) | F8: =SUM(Plan!DT85:FE96) | G8: =SUM(Plan!FG85:GR96) | H8: =SUM(Plan!GT85:IE96) | I8: =SUM(Plan!IG85:JR96) | J8: =SUM(Plan!JT85:LE96) | K8: =SUM(Plan!LG85:MR96) | L8: =SUM(Plan!MT85:OE96) | M8: =SUM(Plan!OG85:PR96) | N8: =SUM(C8:M8)
A9: Social & Multiplayer | B9: 10 | C9: =SUM(Plan!G98:AR107) | D9: =SUM(Plan!AT98:CE107) | E9: =SUM(Plan!CG98:DR107) | F9: =SUM(Plan!DT98:FE107) | G9: =SUM(Plan!FG98:GR107) | H9: =SUM(Plan!GT98:IE107) | I9: =SUM(Plan!IG98:JR107) | J9: =SUM(Plan!JT98:LE107) | K9: =SUM(Plan!LG98:MR107) | L9: =SUM(Plan!MT98:OE107) | M9: =SUM(Plan!OG98:PR107) | N9: =SUM(C9:M9)
A10: Game Bibles | B10: 6 | C10: =SUM(Plan!G109:AR114) | D10: =SUM(Plan!AT109:CE114) | E10: =SUM(Plan!CG109:DR114) | F10: =SUM(Plan!DT109:FE114) | G10: =SUM(Plan!FG109:GR114) | H10: =SUM(Plan!GT109:IE114) | I10: =SUM(Plan!IG109:JR114) | J10: =SUM(Plan!JT109:LE114) | K10: =SUM(Plan!LG109:MR114) | L10: =SUM(Plan!MT109:OE114) | M10: =SUM(Plan!OG109:PR114) | N10: =SUM(C10:M10)
A11: Platform | B11: 19 | C11: =SUM(Plan!G116:AR134) | D11: =SUM(Plan!AT116:CE134) | E11: =SUM(Plan!CG116:DR134) | F11: =SUM(Plan!DT116:FE134) | G11: =SUM(Plan!FG116:GR134) | H11: =SUM(Plan!GT116:IE134) | I11: =SUM(Plan!IG116:JR134) | J11: =SUM(Plan!JT116:LE134) | K11: =SUM(Plan!LG116:MR134) | L11: =SUM(Plan!MT116:OE134) | M11: =SUM(Plan!OG116:PR134) | N11: =SUM(C11:M11)
A12: Live Game | B12: 7 | C12: =SUM(Plan!G136:AR142) | D12: =SUM(Plan!AT136:CE142) | E12: =SUM(Plan!CG136:DR142) | F12: =SUM(Plan!DT136:FE142) | G12: =SUM(Plan!FG136:GR142) | H12: =SUM(Plan!GT136:IE142) | I12: =SUM(Plan!IG136:JR142) | J12: =SUM(Plan!JT136:LE142) | K12: =SUM(Plan!LG136:MR142) | L12: =SUM(Plan!MT136:OE142) | M12: =SUM(Plan!OG136:PR142) | N12: =SUM(C12:M12)
A13: Partner Build | B13: 8 | C13: =SUM(Plan!G144:AR151) | D13: =SUM(Plan!AT144:CE151) | E13: =SUM(Plan!CG144:DR151) | F13: =SUM(Plan!DT144:FE151) | G13: =SUM(Plan!FG144:GR151) | H13: =SUM(Plan!GT144:IE151) | I13: =SUM(Plan!IG144:JR151) | J13: =SUM(Plan!JT144:LE151) | K13: =SUM(Plan!LG144:MR151) | L13: =SUM(Plan!MT144:OE151) | M13: =SUM(Plan!OG144:PR151) | N13: =SUM(C13:M13)
A14: Product Publishing | B14: 7 | C14: =SUM(Plan!G153:AR159) | D14: =SUM(Plan!AT153:CE159) | E14: =SUM(Plan!CG153:DR159) | F14: =SUM(Plan!DT153:FE159) | G14: =SUM(Plan!FG153:GR159) | H14: =SUM(Plan!GT153:IE159) | I14: =SUM(Plan!IG153:JR159) | J14: =SUM(Plan!JT153:LE159) | K14: =SUM(Plan!LG153:MR159) | L14: =SUM(Plan!MT153:OE159) | M14: =SUM(Plan!OG153:PR159) | N14: =SUM(C14:M14)
A16: GRAND TOTAL | C16: =SUM(C2:C15) | D16: =SUM(D2:D15) | E16: =SUM(E2:E15) | F16: =SUM(F2:F15) | G16: =SUM(G2:G15) | H16: =SUM(H2:H15) | I16: =SUM(I2:I15) | J16: =SUM(J2:J15) | ... N16: =SUM(N2:N15)

Sheet Epics & Features
A1: Epic | B1: Feature | C1: Sizing | D1: Current Tier
A2: Player Build | B2: Player Progression | C2: L | D2: T1: R&D
A3: Player Build | B3: Skill System | C3: L | D3: T1: R&D
A4: Player Build | B4: Achievements & Trophies | C4: M | D4: T1: R&D
A5: Player Build | B5: Factions / Reputation | C5: M | D5: T1: R&D
A6: Player Build | B6: FTUE | C6: M | D6: T2: GDD/TDD/Brief
A7: Player Build | B7: Professions | C7: L | D7: T1: R&D
A8: Player Build | B8: Character Management | C8: M | D8: T0: Ideation
A9: Player Build | B9: Character Creation & Customization | C9: L | D9: T1: R&D
A10: Player Build | B10: Garment System | C10: M | D10: T0: Ideation
A11: Player Build | B11: Persona System | C11: M | D11: T1: R&D
A12: Player Build | B12: Emote System | C12: S | D12: T0: Ideation
... A143: Product Publishing | B143: 3rd-party Store Publishing | C143: M | D143: T0: Ideation

Sheet Roles
A1: Role | B1: Discipline | C1: Notes
A2: CEO | B2: Leadership
A3: Creative Director | B3: Leadership
A4: Head of Legal | B4: Leadership
A5: COO | B5: Leadership
A6: HR Manager | B6: Leadership
A7: Executive Producer | B7: Production
A8: Producer | B8: Production
A9: Game Producer | B9: Production
A10: Tech Producer | B10: Production
A11: Art Producer | B11: Production
A12: Game Director | B12: Design
A13: Game Design Lead | B13: Design
... A39: Platform Team | B39: Platform

Sheet Gates
A1: Gate | B1: Phase | D1: Target Tier | E1: Tier Name | F1: Notes
A2: 0 | B2: Concept | D2: T0 | E2: Ideation | F2: Y-doc, pitch, vision lock; all features captured at T0
A3: 1 | B3: Pre-production | D3: T1-T2 | E3: R&D / GDD-TDD-Brief | F3: GDD/TDD/Art briefs for all greenlit features (T2)
A4: 2 | B4: Early Prod | D4: T3 | E4: Prototype | F4: Prototype every feature; many bugs allowed (T3)
A5: 3 | B5: Mid Prod | D5: T4 | E5: MVP | F5: Full MVP scope - heaviest production gate (T4)
A6: 4 | B6: End Prod | D6: T5 | E6: Feature Complete | F6: Feature complete, polish to ship quality (T5)
A7: 5 | B7: Alpha | D7: T6 | E7: Player Tested | F7: Playtest, telemetry, balance pass; gating bugs only
A8: 6 | B8: Beta | D8: T6 | E8: Player Tested | F8: External player feedback, cert prep, content lock
A9: 7 | B9: Launch | D9: T6 | E9: Player Ready | F9: Day-0 readiness, marketing, store, support
A10: 8 | B10: First Release | D10: T6-T7 | E10: Player Ready / Expand | F10: Live monitoring, hotfixes, day-1/7/30 patches
A11: 9 | B11: LS 1 | D11: T7 | E11: Expand | F11: Expansions, new content drops, season cadence (T7)
A12: 10 | B12: LS 2 | D12: T8 | E12: Scale | F12: Optimize / scale post-load, sustain plan (T8)

Sheet Tiers
A1: Tier | B1: Name | C1: Definition
A2: T0 | B2: Ideation | C2: Idea captured, no commitment
A3: T1 | B3: R&D | C3: Research, prototyping intent, technical feasibility
A4: T2 | B4: GDD / TDD / Brief ready | C4: GDD done, TDD done, art brief done
A5: T3 | B5: Prototype | C5: Functional with no skins, can be bugged
A6: T4 | B6: MVP | C6: Limited quality, but full-featured
A7: T5 | B7: Feature Complete (at quality) | C7: Final assets, polished, no scope cuts left
A8: T6 | B8: Player Ready / Tested | C8: Playtest, alpha, beta, telemetry feedback applied
A9: T7 | B9: Expand | C9: Add to feature / content
A10: T8 | B10: Scale | C10: Productional optimization post-load

Sheet Legend
A1: Cell Color / Section | B1: Meaning
B2: Phase super-headers (row 1 of Plan)
A3: Concept | B3: Concept gate (T0 Ideation)
A4: Pre-production | B4: Pre-production gate (T1-T2)
A5: Production | B5: Early / Mid / End Prod gates (T3-T5)
A6: Release | B6: Alpha / Beta / Launch / First Release
A7: Live Service | B7: LS 1 / LS 2
A9: Discipline | B9: Role group color (row 3 of Plan)
A10: Leadership | B10: CEO, Head of Legal, Head of Finance & Ops, HR Manager
A11: Production | B11: Executive / Producer / Game / Tech / Art Producer
A12: Design | B12: Game Director, Design Leads, Designers, Writer
A13: Art | B13: Art Director, Concept, UI/UX, Character/Env/Prop, Anim, Rig, VFX, TA
A14: Engineering | B14: CTO, Tech Lead, Gameplay/Full Stack/Backend/Network
A15: QA | B15: QA
... A17: Platform | B17: Platform Team
A19: Sizing key (col C)
A20: S | B20: Small feature
A21: M | B21: Medium feature
A22: L | B22: Large feature
A24: How to use
A25: Plan sheet | B25: Fill in man-days per (feature, gate, role). Cells are blank by default.
A26: Totals row | B26: Bottom of Plan: SUMs each role column per gate.
A27: Headcount row | B27: Total PW / (gate months * 20 working days). Edit GATE_MONTHS in the script if your durations change.
A28: Summary sheet | B28: Auto-rolls up Plan totals per epic per gate.
A29: Adding rows | B29: Insert rows inside an epic block on Plan. Update Total PW SUM ranges if you extend past the current last data row.
